<?xml version="1.0" encoding="utf-8"?>
<!-- This URDF was automatically created by SolidWorks to URDF Exporter! Originally created by Stephen Brawner (brawner@gmail.com) 
     Commit Version: 1.6.0-1-g15f4949  Build Version: 1.6.7594.29634
     For more information, please see http://wiki.ros.org/sw_urdf_exporter -->
<robot
  name="pm_robot">

  <link name="world">
  </link>
  
  <joint name="world_joint" type="fixed">
    <parent link="world"/>
    <child link="base_link"/>
    <origin
      xyz="0 0 0"
      rpy="0 0 0" />
  </joint>

<!-- <gazebo reference="Nest">
    <material>Gazebo/Black</material>
</gazebo> -->

<!-- <gazebo reference="Component">
    <material>Gazebo/White</material>
</gazebo> -->

  <link
    name="base_link">
    <inertial>
      <origin
        xyz="0.625821801363778 0.570133136306886 0.131114542394431"
        rpy="0 0 0" />
      <mass
        value="185.737269065976" />
      <inertia
        ixx="17.6891686329467"
        ixy="-0.0005539539064769"
        ixz="2.11795920498451E-05"
        iyy="19.5856182457273"
        iyz="0.00180194516552895"
        izz="36.6182068946149" />
    </inertial>
    <visual>
      <origin
        xyz="0 0 0"
        rpy="0 0 0" />
      <geometry>
        <mesh
          filename="file://$(find pm_robot_description)/meshes/base_link.STL" />
      </geometry>
<!--       <material
        name="">
        <color
          rgba="0.792156862745098 0.819607843137255 0.933333333333333 1" />
      </material> -->
    </visual>
    <collision>
      <origin
        xyz="0 0 0"
        rpy="0 0 0" />
      <geometry>
        <mesh
          filename="file://$(find pm_robot_description)/meshes/base_link.STL" />
      </geometry>
    </collision>
  </link>
  <link
    name="X_Axis">
    <inertial>
      <origin
        xyz="0.16919895741484 -0.139025494621401 0.0270399805740182"
        rpy="0 0 0" />
      <mass
        value="3.40836170630821" />
      <inertia
        ixx="0.0248404376541355"
        ixy="-0.000748520694827292"
        ixz="6.13257340524014E-06"
        iyy="0.0088330828502041"
        iyz="-2.4288100595453E-05"
        izz="0.0333342630400324" />
    </inertial>
    <visual>
      <origin
        xyz="0 0 0"
        rpy="0 0 0" />
      <geometry>
        <mesh
          filename="file://$(find pm_robot_description)/meshes/X_Axis.STL" />
      </geometry>
<!--       <material
        name="">
        <color
          rgba="0.792156862745098 0.819607843137255 0.933333333333333 1" />
      </material> -->
    </visual>
    <collision>
      <origin
        xyz="0 0 0"
        rpy="0 0 0" />
      <geometry>
        <mesh
          filename="file://$(find pm_robot_description)/meshes/X_Axis.STL" />
      </geometry>
    </collision>
  </link>
  <joint
    name="X_Axis_Joint"
    type="prismatic">
    <origin
      xyz="0.19 0.5545 0.56"
      rpy="0 0 0" />
    <parent
      link="base_link" />
    <child
      link="X_Axis" />
    <axis
      xyz="-1 0 0" />
    <limit
      lower="-0.745"
      upper="0.055"
      effort="100"
      velocity="0.05" />
  </joint>
  <link
    name="Y_Axis">
    <inertial>
      <origin
        xyz="0.0644731605204091 0.335953761487189 0.0959734258135516"
        rpy="0 0 0" />
      <mass
        value="5.14878388645621" />
      <inertia
        ixx="0.0689971056038874"
        ixy="-5.48415730832886E-06"
        ixz="0.000161589759460467"
        iyy="0.0347519976611458"
        iyz="-0.00648361648669565"
        izz="0.0562521130143104" />
    </inertial>
    <visual>
      <origin
        xyz="0 0 0"
        rpy="0 0 0" />
      <geometry>
        <mesh
          filename="file://$(find pm_robot_description)/meshes/Y_Axis.STL" />
      </geometry>
<!--       <material
        name="">
        <color
          rgba="0.792156862745098 0.819607843137255 0.933333333333333 1" />
      </material> -->
    </visual>
    <collision>
      <origin
        xyz="0 0 0"
        rpy="0 0 0" />
      <geometry>
        <mesh
          filename="file://$(find pm_robot_description)/meshes/Y_Axis.STL" />
      </geometry>
    </collision>
  </link>
  <joint
    name="Y_Axis_Joint"
    type="prismatic">
    <origin
      xyz="0.1115 -0.39197 0.0625"
      rpy="0 0 0" />
    <parent
      link="X_Axis" />
    <child
      link="Y_Axis" />
    <axis
      xyz="0 -1 0" />
    <limit
      lower="-0.425"
      upper="0.2505"
      effort="100"
      velocity="0.05" />
  </joint>
  <link
    name="Z_Axis">
    <inertial>
      <origin
        xyz="0.0549049098594834 0.0430017751887579 -0.271974089543362"
        rpy="0 0 0" />
      <mass
        value="2.90435657697672" />
      <inertia
        ixx="0.0172042502712429"
        ixy="-1.43162614116986E-05"
        ixz="0.000234498173213759"
        iyy="0.0221198084238349"
        iyz="9.06231760054573E-05"
        izz="0.00612331848936254" />
    </inertial>
    <visual>
      <origin
        xyz="0 0 0"
        rpy="0 0 0" />
      <geometry>
        <mesh
          filename="file://$(find pm_robot_description)/meshes/Z_Axis.STL" />
      </geometry>
<!--       <material
        name="">
        <color
          rgba="0.792156862745098 0.819607843137255 0.933333333333333 1" />
      </material> -->
    </visual>
    <collision>
      <origin
        xyz="0 0 0"
        rpy="0 0 0" />
      <geometry>
        <mesh
          filename="file://$(find pm_robot_description)/meshes/Z_Axis.STL" />
      </geometry>
    </collision>
  </link>
  <!---Gravity off-->
  <gazebo reference="Z_Axis">
    <turnGravityOff>true</turnGravityOff>
  </gazebo>
  <joint
    name="Z_Axis_Joint"
    type="prismatic">
    <origin
      xyz="-0.000999999553101816 0.496199999543101 0.2825180193463"
      rpy="0 0 0" />
    <parent
      link="Y_Axis" />
    <child
      link="Z_Axis" />
    <axis
      xyz="0 0 -1" />
    <limit
      lower="-0.05262"
      upper="0.055"
      effort="100"
      velocity="0.05" />
  </joint>
  <link
    name="Gripper_Rot_Plate">
    <inertial>
      <origin
        xyz="2.0103346298761E-07 1.7706926014327E-07 -0.0164220765723002"
        rpy="0 0 0" />
      <mass
        value="0.11029725831735" />
      <inertia
        ixx="8.79764941917058E-05"
        ixy="-1.83626185977477E-10"
        ixz="-1.48320232213546E-10"
        iyy="8.79759415900838E-05"
        iyz="-1.27560286892208E-10"
        izz="0.000165659871028387" />
    </inertial>
    <visual>
      <origin
        xyz="0 0 0"
        rpy="0 0 0" />
      <geometry>
        <mesh
          filename="file://$(find pm_robot_description)/meshes/Gripper_Rot_Plate.STL" />
      </geometry>
<!--       <material
        name="">
        <color
          rgba="0.792156862745098 0.819607843137255 0.933333333333333 1" />
      </material> -->
    </visual>
    <collision>
      <origin
        xyz="0 0 0"
        rpy="0 0 0" />
      <geometry>
        <mesh
          filename="file://$(find pm_robot_description)/meshes/Gripper_Rot_Plate.STL" />
      </geometry>
    </collision>
  </link>
  <!---Gravity off-->
  <gazebo reference="Gripper_Rot_Plate">
    <turnGravityOff>true</turnGravityOff>
  </gazebo>
  <joint
    name="Gripper_Rot_Plate_Joint"
    type="revolute">
    <origin
      xyz="0.00750000000002338 0.0900000062570287 -0.389499999999991"
      rpy="0 0 0" />
    <parent
      link="Z_Axis" />
    <child
      link="Gripper_Rot_Plate" />
    <axis
      xyz="0 0 1" />
    <limit
      lower="0"
      upper="628319"
      effort="100"
      velocity="0.05" />
  </joint>
  <link
    name="Gripper">
    <inertial>
      <origin
        xyz="0.000135108807628681 -1.05111383998813E-05 -0.0292448632131201"
        rpy="0 0 0" />
      <mass
        value="0.127647896986229" />
      <inertia
        ixx="2.5142711578718E-05"
        ixy="-1.59474432850153E-08"
        ixz="3.3525019883474E-09"
        iyy="2.54173373628528E-05"
        iyz="4.55516572819561E-10"
        izz="4.13581383274998E-05" />
    </inertial>
    <visual>
      <origin
        xyz="0 0 0"
        rpy="0 0 0" />
      <geometry>
        <mesh
          filename="file://$(find pm_robot_description)/meshes/Gripper.STL" />
      </geometry>
<!--       <material
        name="">
        <color
          rgba="0.792156862745098 0.819607843137255 0.933333333333333 1" />
      </material> -->
    </visual>
    <collision>
      <origin
        xyz="0 0 0"
        rpy="0 0 0" />
      <geometry>
        <mesh
          filename="file://$(find pm_robot_description)/meshes/Gripper.STL" />
      </geometry>
    </collision>
  </link>
  <!---Gravity off-->
  <gazebo reference="Gripper">
    <turnGravityOff>true</turnGravityOff>
  </gazebo>
  <joint
    name="Gripper_Joint"
    type="fixed">
    <origin
      xyz="0 0 -0.0255000000000101"
      rpy="0 0 0" />
    <parent
      link="Gripper_Rot_Plate" />
    <child
      link="Gripper" />
    <axis
      xyz="0 0 0" />
  </joint>
  <link
    name="Glue_Cartridge_Flap">
    <inertial>
      <origin
        xyz="0.0700781843320127 0.0170691077164346 -0.0129807443134584"
        rpy="0 0 0" />
      <mass
        value="0.0179277924431146" />
      <inertia
        ixx="4.17419773394052E-06"
        ixy="1.29835566651964E-07"
        ixz="-6.29537316660378E-08"
        iyy="5.0332526265048E-06"
        iyz="-9.02306176061445E-09"
        izz="4.11888432036329E-06" />
    </inertial>
    <visual>
      <origin
        xyz="0 0 0"
        rpy="0 0 0" />
      <geometry>
        <mesh
          filename="file://$(find pm_robot_description)/meshes/Glue_Cartridge_Flap.STL" />
      </geometry>
<!--       <material
        name="">
        <color
          rgba="0.792156862745098 0.819607843137255 0.933333333333333 1" />
      </material> -->
    </visual>
    <collision>
      <origin
        xyz="0 0 0"
        rpy="0 0 0" />
      <geometry>
        <mesh
          filename="file://$(find pm_robot_description)/meshes/Glue_Cartridge_Flap.STL" />
      </geometry>
    </collision>
  </link>
  <!---Gravity off-->
  <gazebo reference="Glue_Cartridge_Flap">
    <turnGravityOff>true</turnGravityOff>
  </gazebo>
  <joint
    name="Glue_Cartridge_Flap_Joint"
    type="prismatic">
    <origin
      xyz="0.0750000000000233 0.0545000062570286 -0.412499999999991"
      rpy="0 0 0" />
    <parent
      link="Z_Axis" />
    <child
      link="Glue_Cartridge_Flap" />
    <axis
      xyz="-1 0 0" />
    <limit
      lower="0"
      upper="0.02"
      effort="100"
      velocity="0.05" />
  </joint>
  <link
    name="Glue_Cartridge">
    <inertial>
      <origin
        xyz="0.00252184437967673 0.0162311247825426 -0.0902228052383323"
        rpy="0 0 0" />
      <mass
        value="0.0725671789065893" />
      <inertia
        ixx="3.42933852013293E-05"
        ixy="-1.91967791577504E-07"
        ixz="5.62664387056898E-08"
        iyy="3.4047535660396E-05"
        iyz="-5.6636413986979E-07"
        izz="1.14639175061085E-05" />
    </inertial>
    <visual>
      <origin
        xyz="0 0 0"
        rpy="0 0 0" />
      <geometry>
        <mesh
          filename="file://$(find pm_robot_description)/meshes/Glue_Cartridge.STL" />
      </geometry>
<!--       <material
        name="">
        <color
          rgba="0.792156862745098 0.819607843137255 0.933333333333333 1" />
      </material> -->
    </visual>
    <collision>
      <origin
        xyz="0 0 0"
        rpy="0 0 0" />
      <geometry>
        <mesh
          filename="file://$(find pm_robot_description)/meshes/Glue_Cartridge.STL" />
      </geometry>
    </collision>
  </link>
  <!---Gravity off-->
  <gazebo reference="Glue_Cartridge">
    <turnGravityOff>true</turnGravityOff>
  </gazebo>
  <joint
    name="Glue_Cartridge_Joint"
    type="prismatic">
    <origin
      xyz="0.171500000000024 0.0582000062570286 -0.341999999999991"
      rpy="0 0 0" />
    <parent
      link="Z_Axis" />
    <child
      link="Glue_Cartridge" />
    <axis
      xyz="0 0 1" />
    <limit
      lower="0"
      upper="0.04"
      effort="100"
      velocity="0.05" />
  </joint>
  <link
    name="EQ">
    <inertial>
      <origin
        xyz="-0.000295411016381641 0.0248543962427798 0.0574291260378159"
        rpy="0 0 0" />
      <mass
        value="0.398291319329287" />
      <inertia
        ixx="0.00156701563987073"
        ixy="-4.41604324049231E-06"
        ixz="9.92168040657486E-08"
        iyy="0.00155258685914303"
        iyz="1.49787524994666E-06"
        izz="0.000122318061840883" />
    </inertial>
    <visual>
      <origin
        xyz="0 0 0"
        rpy="0 0 0" />
      <geometry>
        <mesh
          filename="file://$(find pm_robot_description)/meshes/EQ.STL" />
      </geometry>
<!--       <material
        name="">
        <color
          rgba="0.792156862745098 0.819607843137255 0.933333333333333 1" />
      </material> -->
    </visual>
    <collision>
      <origin
        xyz="0 0 0"
        rpy="0 0 0" />
      <geometry>
        <mesh
          filename="file://$(find pm_robot_description)/meshes/EQ.STL" />
      </geometry>
    </collision>
  </link>
  <!---Gravity off-->
  <gazebo reference="EQ">
    <turnGravityOff>true</turnGravityOff>
  </gazebo>
  <joint
    name="EQ_Joint"
    type="prismatic">
    <origin
      xyz="0.236500000000024 0.0322575758254202 -0.310499999999992"
      rpy="0 0 0" />
    <parent
      link="Z_Axis" />
    <child
      link="EQ" />
    <axis
      xyz="0 0 1" />
    <limit
      lower="0"
      upper="0.02"
      effort="100"
      velocity="0.05" />
  </joint>
  <link
    name="Camera_Module_Z_Axis">
    <inertial>
      <origin
        xyz="0.0116313616057115 0.0214231207637281 -0.0632876276111702"
        rpy="0 0 0" />
      <mass
        value="0.0744906107551854" />
      <inertia
        ixx="3.47731720414153E-05"
        ixy="6.43752140750256E-10"
        ixz="3.28409092724849E-07"
        iyy="3.75323274030922E-05"
        iyz="1.11954348594254E-07"
        izz="9.810378338093E-06" />
    </inertial>
    <visual>
      <origin
        xyz="0 0 0"
        rpy="0 0 0" />
      <geometry>
        <mesh
          filename="file://$(find pm_robot_description)/meshes/Camera_Module_Z_Axis.STL" />
      </geometry>
<!--       <material
        name="">
        <color
          rgba="0.792156862745098 0.819607843137255 0.933333333333333 1" />
      </material> -->
    </visual>
    <collision>
      <origin
        xyz="0 0 0"
        rpy="0 0 0" />
      <geometry>
        <mesh
          filename="file://$(find pm_robot_description)/meshes/Camera_Module_Z_Axis.STL" />
      </geometry>
    </collision>
  </link>
    <!---Gravity off-->
  <gazebo reference="Camera_Module_Z_Axis">
    <turnGravityOff>true</turnGravityOff>
  </gazebo>
  <joint
    name="Camera_Module_Z_Axis_Joint"
    type="fixed">
    <origin
      xyz="0.0795000000000243 0.068500020970708 -0.233999999999991"
      rpy="0 0 0" />
    <parent
      link="Z_Axis" />
    <child
      link="Camera_Module_Z_Axis" />
    <axis
      xyz="0 0 0" />
  </joint>

  <link
    name="Test_Station">
    <inertial>
      <origin
        xyz="0.0375 0.109867595364853 0.143148862667039"
        rpy="0 0 0" />
      <mass
        value="1.39099524679326" />
      <inertia
        ixx="0.00780193904512034"
        ixy="-2.61716248057058E-14"
        ixz="-3.61572424102462E-21"
        iyy="0.00547600691976027"
        iyz="-9.87499782880815E-10"
        izz="0.00281708795214925" />
    </inertial>
    <visual>
      <origin
        xyz="0 0 0"
        rpy="0 0 0" />
      <geometry>
        <mesh
          filename="file://$(find pm_robot_description)/meshes/Test_Station.STL" />
      </geometry>
<!--       <material
        name="">
        <color
          rgba="0.792156862745098 0.819607843137255 0.933333333333333 1" />
      </material> -->
    </visual>
    <collision>
      <origin
        xyz="0 0 0"
        rpy="0 0 0" />
      <geometry>
        <mesh
          filename="file://$(find pm_robot_description)/meshes/Test_Station.STL" />
      </geometry>
    </collision>
  </link>
  <joint
    name="Test_Station_Joint"
    type="fixed">
    <origin
      xyz="1.0625 0.6845 0.1"
      rpy="0 0 0" />
    <parent
      link="base_link" />
    <child
      link="Test_Station" />
    <axis
      xyz="0 0 0" />
  </joint>
  <link
    name="Gonio_Base_Rigth">
    <inertial>
      <origin
        xyz="-0.443310661236087 0.0330000000000467 -0.10131041089702"
        rpy="0 0 0" />
      <mass
        value="0.735149712395274" />
      <inertia
        ixx="0.00216091772202082"
        ixy="1.66756120275789E-18"
        ixz="2.02637515337738E-06"
        iyy="0.00218184071743384"
        iyz="8.52621696064458E-20"
        izz="0.000537837036237896" />
    </inertial>
    <visual>
      <origin
        xyz="0 0 0"
        rpy="0 0 0" />
      <geometry>
        <mesh
          filename="file://$(find pm_robot_description)/meshes/Gonio_Base_Rigth.STL" />
      </geometry>
<!--       <material
        name="">
        <color
          rgba="0.792156862745098 0.819607843137255 0.933333333333333 1" />
      </material> -->
    </visual>
    <collision>
      <origin
        xyz="0 0 0"
        rpy="0 0 0" />
      <geometry>
        <mesh
          filename="file://$(find pm_robot_description)/meshes/Gonio_Base_Rigth.STL" />
      </geometry>
    </collision>
  </link>
  <joint
    name="Gonio_base_Rigth_Joint"
    type="fixed">
    <origin
      xyz="0.843436798933783 0.769499999999991 0.297531903269611"
      rpy="0 0.00124847209373138 0" />
    <parent
      link="base_link" />
    <child
      link="Gonio_Base_Rigth" />
    <axis
      xyz="0 0 0" />
  </joint>
  <link
    name="Stage_1_Gonio_Right">
    <inertial>
      <origin
        xyz="0.0450000285629691 0.0154464744552945 0.180028793226625"
        rpy="0 0 0" />
      <mass
        value="0.0706349432835735" />
      <inertia
        ixx="3.36962706733939E-05"
        ixy="-7.72258833183303E-11"
        ixz="-1.91981813462905E-11"
        iyy="1.8004068123271E-05"
        iyz="-1.39266767162838E-07"
        izz="4.86217530226209E-05" />
    </inertial>
    <visual>
      <origin
        xyz="0 0 0"
        rpy="0 0 0" />
      <geometry>
        <mesh
          filename="file://$(find pm_robot_description)/meshes/Stage_1_Gonio_Right.STL" />
      </geometry>
<!--        <material
        name="">
        <color
          rgba="0.792156862745098 0.819607843137255 0.933333333333333 1" />
      </material>  -->
    </visual>
    <collision>
      <origin
        xyz="0 0 0"
        rpy="0 0 0" />
      <geometry>
        <mesh
          filename="file://$(find pm_robot_description)/meshes/Stage_1_Gonio_Right.STL" />
      </geometry>
    </collision>
  </link>
  <joint
    name="Stage_1_Gonio_Right_Joint"
    type="fixed">
    <origin
      xyz="-0.488205660861556 0.00050000000005054 -0.185441558777103"
      rpy="0 -0.00124847209373138 0" />
    <parent
      link="Gonio_Base_Rigth" />
    <child
      link="Stage_1_Gonio_Right" />
    <axis
      xyz="0 0 0" />
  </joint>
  <link
    name="Gonio_Right_Stage_1_Upper">
    <inertial>
      <origin
        xyz="0.0236093552066096 0.000777611453360041 -0.07883096150979"
        rpy="0 0 0" />
      <mass
        value="0.135485840705969" />
      <inertia
        ixx="4.16210427703093E-05"
        ixy="1.17487642350012E-09"
        ixz="-1.10761881698597E-07"
        iyy="6.29240886667246E-05"
        iyz="-3.38034194495186E-07"
        izz="9.71875209897851E-05" />
    </inertial>
    <visual>
      <origin
        xyz="0 0 0"
        rpy="0 0 0" />
      <geometry>
        <mesh
          filename="file://$(find pm_robot_description)/meshes/Gonio_Right_Stage_1_Upper.STL" />
      </geometry>
<!--       <material
        name="">
        <color
          rgba="0.792156862745098 0.819607843137255 0.933333333333333 1" />
      </material> -->
    </visual>
    <collision>
      <origin
        xyz="0 0 0"
        rpy="0 0 0" />
      <geometry>
        <mesh
          filename="file://$(find pm_robot_description)/meshes/Gonio_Right_Stage_1_Upper.STL" />
      </geometry>
    </collision>
  </link>
  <joint
    name="Gonio_Right_Stage_1_Upper_joint"
    type="revolute">
    <origin
      xyz="0.0125000000000001 0.0325000000000001 0.281999999999999"
      rpy="0 0 0" />
    <parent
      link="Stage_1_Gonio_Right" />
    <child
      link="Gonio_Right_Stage_1_Upper" />
    <axis
      xyz="1 0 0" />
    <limit
      lower="-0.087266"
      upper="0.087266"
      effort="100"
      velocity="0.1" />
  </joint>
  <link
    name="Gonio_Right_Stage_2_Upper">
    <inertial>
      <origin
        xyz="-6.53148646279078E-10 -0.0325000008448236 -0.0578599602398864"
        rpy="0 0 0" />
      <mass
        value="0.0546397592722759" />
      <inertia
        ixx="2.38958843339078E-05"
        ixy="-1.0219765031195E-11"
        ixz="8.98389909344655E-13"
        iyy="1.83573881738552E-05"
        iyz="-3.15839883014258E-13"
        izz="3.93608769988889E-05" />
    </inertial>
    <visual>
      <origin
        xyz="0 0 0"
        rpy="0 0 0" />
      <geometry>
        <mesh
          filename="file://$(find pm_robot_description)/meshes/Gonio_Right_Stage_2_Upper.STL" />
      </geometry>
<!--       <material
        name="">
        <color
          rgba="0.792156862745098 0.819607843137255 0.933333333333333 1" />
      </material> -->
    </visual>
    <collision>
      <origin
        xyz="0 0 0"
        rpy="0 0 0" />
      <geometry>
        <mesh
          filename="file://$(find pm_robot_description)/meshes/Gonio_Right_Stage_2_Upper.STL" />
      </geometry>
    </collision>
  </link>
  <joint
    name="Gonio_Right_Stage_2_Upper_Joint"
    type="revolute">
    <origin
      xyz="0.0325 0.0324984184257152 0.000320624121260105"
      rpy="0.00986554689296988 0.00243647716593582 2.40379358152113E-05" />
    <parent
      link="Gonio_Right_Stage_1_Upper" />
    <child
      link="Gonio_Right_Stage_2_Upper" />
    <axis
      xyz="0 -1 0" />
    <limit
      lower="-0.17453"
      upper="0.17453"
      effort="100"
      velocity="0.1" />
  </joint>
  <link
    name="Nest">
    <inertial>
      <origin
        xyz="0.032450872460221 0.0324929107955899 0.0216564841431486"
        rpy="0 0 0" />
      <mass
        value="0.133934804260549" />
      <inertia
        ixx="3.05433990945617E-05"
        ixy="-2.55507778379188E-10"
        ixz="-1.74866992826515E-08"
        iyy="4.8078789038224E-05"
        iyz="2.24246440407081E-09"
        izz="7.18729232272563E-05" />
    </inertial>
    <visual>
      <origin
        xyz="0 0 0"
        rpy="0 0 0" />
      <geometry>
        <mesh
          filename="file://$(find pm_robot_description)/meshes/Nest.STL" />
      </geometry>
<!--       <material
        name="">
        <color
          rgba="0.792156862745098 0.819607843137255 0.933333333333333 1" />
      </material> -->
    </visual>
    <collision>
      <origin
        xyz="0 0 0"
        rpy="0 0 0" />
      <geometry>
        <mesh
          filename="file://$(find pm_robot_description)/meshes/Nest.STL" />
      </geometry>
    </collision>
  </link>
  <joint
    name="Nest_Joint"
    type="fixed">
    <origin
      xyz="-0.0324999999999999 -0.065 -0.0499999999999998"
      rpy="0 0 0" />
    <parent
      link="Gonio_Right_Stage_2_Upper" />
    <child
      link="Nest" />
    <axis
      xyz="0 0 0" />
  </joint>
<!-- 
  <link
    name="Component">
    <inertial>
      <origin
        xyz="0.0347500000000016 0.0327000000000096 0.0533550000000003"
        rpy="0 0 0" />
      <mass
        value="0.00104831550000006" />
      <inertia
        ixx="3.55496103757146E-08"
        ixy="1.89981381540481E-23"
        ixz="2.41620205931236E-23"
        iyy="8.15217394357171E-08"
        iyz="8.32325538551038E-24"
        izz="1.16560453252507E-07" />
    </inertial>
    <visual>
      <origin
        xyz="0 0 0"
        rpy="0 0 0" />
      <geometry>
        <mesh
          filename="package://robot_image_recognition/meshes/Component.STL" />
      </geometry>
      <material
        name="">
        <color
          rgba="0.792156862745098 0.819607843137255 0.933333333333333 2" />
      </material>
    </visual>
    <collision>
      <origin
        xyz="0 0 0"
        rpy="0 0 0" />
      <geometry>
        <mesh
          filename="package://robot_image_recognition/meshes/Component.STL" />
      </geometry>
    </collision>
  </link>
  <joint
    name="Component_Joint"
    type="fixed">
    <origin
      xyz="0 0 0"
      rpy="0 0 0" />
    <parent
      link="Nest" />
    <child
      link="Component" />
    <axis
      xyz="0 0 0" />
  </joint> -->

  <link
    name="Camera_System">
    <inertial>
      <origin
        xyz="0.0505028321627497 0.194735930802516 0.146786757354195"
        rpy="0 0 0" />
      <mass
        value="2.8858378823955" />
      <inertia
        ixx="0.0184869737843273"
        ixy="1.26297079346321E-05"
        ixz="3.42211569734802E-06"
        iyy="0.0045547035395917"
        iyz="-9.47292848293822E-05"
        izz="0.0194720270517019" />
    </inertial>
    <visual>
      <origin
        xyz="0 0 0"
        rpy="0 0 0" />
      <geometry>
        <mesh
          filename="file://$(find pm_robot_description)/meshes/Camera_System.STL" />
      </geometry>
<!--       <material
        name="">
        <color
          rgba="0.792156862745098 0.819607843137255 0.933333333333333 1" />
      </material> -->
    </visual>
    <collision>
      <origin
        xyz="0 0 0"
        rpy="0 0 0" />
      <geometry>
        <mesh
          filename="file://$(find pm_robot_description)/meshes/Camera_System.STL" />
      </geometry>
    </collision>
  </link>
  <joint
    name="Camera_System_Joint"
    type="fixed">
    <origin
      xyz="0.6025 0.5075 0.1"
      rpy="0 0 0" />
    <parent
      link="base_link" />
    <child
      link="Camera_System" />
    <axis
      xyz="0 0 0" />
  </joint>
  <link
    name="Camera_Calibration">
    <inertial>
      <origin
        xyz="-2.23806848806962E-05 -0.0716494371536874 0.0040939089037404"
        rpy="0 0 0" />
      <mass
        value="0.0326858647412389" />
      <inertia
        ixx="2.04982158767326E-05"
        ixy="-1.61006130053567E-08"
        ixz="3.66083708051192E-11"
        iyy="2.64269352598525E-06"
        iyz="-4.64472618194221E-07"
        izz="2.23690961977999E-05" />
    </inertial>
    <visual>
      <origin
        xyz="0 0 0"
        rpy="0 0 0" />
      <geometry>
        <mesh
          filename="file://$(find pm_robot_description)/meshes/Camera_Calibration.STL" />
      </geometry>
<!--       <material
        name="">
        <color
          rgba="0.792156862745098 0.819607843137255 0.933333333333333 1" />
      </material> -->
    </visual>
    <collision>
      <origin
        xyz="0 0 0"
        rpy="0 0 0" />
      <geometry>
        <mesh
          filename="file://$(find pm_robot_description)/meshes/Camera_Calibration.STL" />
      </geometry>
    </collision>
  </link>
  <joint
    name="Camera_Calibartion_Joint"
    type="prismatic">
    <origin
      xyz="0.065 0.4615 0.293"
      rpy="0 0 0" />
    <parent
      link="Camera_System" />
    <child
      link="Camera_Calibration" />
    <axis
      xyz="0 1 0" />
    <limit
      lower="-0.04"
      upper="0.0"
      effort="100"
      velocity="0.05" />
  </joint>
  <link
    name="Gonio_Base_Left">
    <inertial>
      <origin
        xyz="0.126941450046363 0.123518998015631 0.100678856473502"
        rpy="0 0 0" />
      <mass
        value="4.82459847582554" />
      <inertia
        ixx="0.011510655159352"
        ixy="-3.33565784736191E-05"
        ixz="1.45496624991337E-06"
        iyy="0.0188665286335149"
        iyz="2.60234058906314E-05"
        izz="0.0269849279870219" />
    </inertial>
    <visual>
      <origin
        xyz="0 0 0"
        rpy="0 0 0" />
      <geometry>
        <mesh
          filename="file://$(find pm_robot_description)/meshes/Gonio_Base_Left.STL" />
      </geometry>
<!--       <material
        name="">
        <color
          rgba="0.792156862745098 0.819607843137255 0.933333333333333 1" />
      </material> -->
    </visual>
    <collision>
      <origin
        xyz="0 0 0"
        rpy="0 0 0" />
      <geometry>
        <mesh
          filename="file://$(find pm_robot_description)/meshes/Gonio_Base_Left.STL" />
      </geometry>
    </collision>
  </link>
  <joint
    name="Gonio_Base_Left_Joint"
    type="fixed">
    <origin
      xyz="0.752500000000035 0.684500000000037 0.100000000000003"
      rpy="0 0 0" />
    <parent
      link="base_link" />
    <child
      link="Gonio_Base_Left" />
    <axis
      xyz="0 0 0" />
  </joint>
  <link
    name="Gonio_Left_Stage_1_Upper">
    <inertial>
      <origin
        xyz="-0.0997824878967629 -0.00877925652714914 -0.0446785627316291"
        rpy="0 0 0" />
      <mass
        value="0.578798857286943" />
      <inertia
        ixx="0.000400478324367352"
        ixy="-0.000129239522587823"
        ixz="-7.82346515363914E-07"
        iyy="0.00157904583991977"
        iyz="5.25968237719547E-06"
        izz="0.00188005175520343" />
    </inertial>
    <visual>
      <origin
        xyz="0 0 0"
        rpy="0 0 0" />
      <geometry>
        <mesh
          filename="file://$(find pm_robot_description)/meshes/Gonio_Left_Stage_1_Upper.STL" />
      </geometry>
<!--       <material
        name="">
        <color
          rgba="0.792156862745098 0.819607843137255 0.933333333333333 1" />
      </material> -->
    </visual>
    <collision>
      <origin
        xyz="0 0 0"
        rpy="0 0 0" />
      <geometry>
        <mesh
          filename="file://$(find pm_robot_description)/meshes/Gonio_Left_Stage_1_Upper.STL" />
      </geometry>
    </collision>
  </link>
  <joint
    name="Gonio_Left_Stage_1_Upper_Joint"
    type="revolute">
    <origin
      xyz="0.156499999999957 0.109999999999947 0.212499999999997"
      rpy="0 0 0" />
    <parent
      link="Gonio_Base_Left" />
    <child
      link="Gonio_Left_Stage_1_Upper" />
    <axis
      xyz="1 0 0" />
    <limit
      lower="-0.78539816339745"
      upper="0.78539816339745"
      effort="100"
      velocity="0.1" />
  </joint>
  <link
    name="Gonio_Left_Stage_2_Upper">
    <inertial>
      <origin
        xyz="-2.64677118601286E-05 -0.0250000000001234 -0.0212004406894863"
        rpy="0 0 0" />
      <mass
        value="0.0270626702476323" />
      <inertia
        ixx="6.08759497527378E-06"
        ixy="4.08430684508571E-14"
        ixz="4.39226594546324E-09"
        iyy="4.36785275766636E-06"
        iyz="-1.45383292013094E-16"
        izz="9.60639482996178E-06" />
    </inertial>
    <visual>
      <origin
        xyz="0 0 0"
        rpy="0 0 0" />
      <geometry>
        <mesh
          filename="file://$(find pm_robot_description)/meshes/Gonio_Left_Stage_2_Upper.STL" />
      </geometry>
<!--       <material
        name="">
        <color
          rgba="0.792156862745098 0.819607843137255 0.933333333333333 1" />
      </material> -->
    </visual>
    <collision>
      <origin
        xyz="0 0 0"
        rpy="0 0 0" />
      <geometry>
        <mesh
          filename="file://$(find pm_robot_description)/meshes/Gonio_Left_Stage_2_Upper.STL" />
      </geometry>
    </collision>
  </link>
  <joint
    name="Gonio_Left_Stage_2_Upper_Joint"
    type="revolute">
    <origin
      xyz="-0.04 0.025 0"
      rpy="0 0 0" />
    <parent
      link="Gonio_Left_Stage_1_Upper" />
    <child
      link="Gonio_Left_Stage_2_Upper" />
    <axis
      xyz="0 -1 0" />
    <limit
      lower="-0.78539816339745"
      upper="0.78539816339745"
      effort="100"
      velocity="0.1" />
  </joint>
  <link
    name="Gonio_Right_Mount_Lower">
    <inertial>
      <origin
        xyz="0.0162416232097771 0.0179266836523483 0.0446054201820039"
        rpy="0 0 0" />
      <mass
        value="0.193859196114997" />
      <inertia
        ixx="6.6965131704231E-05"
        ixy="1.79270793281868E-07"
        ixz="9.94006466314354E-07"
        iyy="0.000515179692751325"
        iyz="1.1170065098574E-06"
        izz="0.000471145863687032" />
    </inertial>
    <visual>
      <origin
        xyz="0 0 0"
        rpy="0 0 0" />
      <geometry>
        <mesh
          filename="file://$(find pm_robot_description)/meshes/Gonio_Right_Mount_Lower.STL" />
      </geometry>
<!--       <material
        name="">
        <color
          rgba="0.792156862745098 0.819607843137255 0.933333333333333 1" />
      </material> -->
    </visual>
    <collision>
      <origin
        xyz="0 0 0"
        rpy="0 0 0" />
      <geometry>
        <mesh
          filename="file://$(find pm_robot_description)/meshes/Gonio_Right_Mount_Lower.STL" />
      </geometry>
    </collision>
  </link>
<joint
    name="Gonio_Right_Mount_Lower_joint"
    type="fixed">
    <origin
      xyz="-0.0255632010662045 -0.05 -0.0149680967303876"
      rpy="0 0.00124847209372143 0" />
    <parent
      link="Gonio_Left_Stage_2_Upper" />
    <child
      link="Gonio_Right_Mount_Lower" />
    <axis
      xyz="0 0 0" />
  </joint>
  <link
    name="Gonio_Right_Mount_Upper">
    <inertial>
      <origin
        xyz="0.0138876332089552 0.0253601886212102 0.0864002192139908"
        rpy="0 0 0" />
      <mass
        value="0.0762325967846099" />
      <inertia
        ixx="1.37177472529419E-05"
        ixy="-1.46120092158232E-07"
        ixz="-6.17955623619177E-07"
        iyy="0.000262744933743385"
        iyz="8.65502713401381E-08"
        izz="0.000253259614960968" />
    </inertial>
    <visual>
      <origin
        xyz="0 0 0"
        rpy="0 0 0" />
      <geometry>
        <mesh
          filename="file://$(find pm_robot_description)/meshes/Gonio_Right_Mount_Upper.STL" />
      </geometry>
<!--       <material
        name="">
        <color
          rgba="0.792156862745098 0.819607843137255 0.933333333333333 1" />
      </material> -->
    </visual>
    <collision>
      <origin
        xyz="0 0 0"
        rpy="0 0 0" />
      <geometry>
        <mesh
          filename="file://$(find pm_robot_description)/meshes/Gonio_Right_Mount_Upper.STL" />
      </geometry>
    </collision>
  </link>
  <joint
    name="Gonio_Right_Mount_Upper_Joint"
    type="fixed">
    <origin
      xyz="0.000544493897539577 0 0"
      rpy="0 -0.00124847209372143 0" />
    <parent
      link="Gonio_Right_Mount_Lower" />
    <child
      link="Gonio_Right_Mount_Upper" />
    <axis
      xyz="0 0 0" />
  </joint>
  <link
    name="UV_Cart_Left">
    <inertial>
      <origin
        xyz="0.109018366442935 -0.0253104400388921 0.0106949485904486"
        rpy="0 0 0" />
      <mass
        value="0.127959263611525" />
      <inertia
        ixx="5.21591452075977E-05"
        ixy="6.20383441116901E-08"
        ixz="-1.12100819961438E-07"
        iyy="6.05583187276661E-05"
        iyz="5.20562066916109E-08"
        izz="0.0001087127585747" />
    </inertial>
    <visual>
      <origin
        xyz="0 0 0"
        rpy="0 0 0" />
      <geometry>
        <mesh
          filename="file://$(find pm_robot_description)/meshes/UV_Cart_Left.STL" />
      </geometry>
<!--       <material
        name="">
        <color
          rgba="0.792156862745098 0.819607843137255 0.933333333333333 1" />
      </material> -->
    </visual>
    <collision>
      <origin
        xyz="0 0 0"
        rpy="0 0 0" />
      <geometry>
        <mesh
          filename="file://$(find pm_robot_description)/meshes/UV_Cart_Left.STL" />
      </geometry>
    </collision>
  </link>
  <joint
    name="UV_Cart_Left_Joint"
    type="prismatic">
    <origin
      xyz="0.00649999999276624 0.231179999755626 0.252599999998818"
      rpy="0 0 0" />
    <parent
      link="Gonio_Base_Left" />
    <child
      link="UV_Cart_Left" />
    <axis
      xyz="-1 0 0" />
    <limit
      lower="-0.05"
      upper="0.095"
      effort="100"
      velocity="0.05" />
  </joint>
  <link
    name="UV_Module_Left">
    <inertial>
      <origin
        xyz="-0.00149625704690598 -0.0153546654161227 0.0150907885908851"
        rpy="0 0 0" />
      <mass
        value="0.119915229322348" />
      <inertia
        ixx="8.58688560134339E-05"
        ixy="-9.33412693374149E-06"
        ixz="-2.12947224034943E-07"
        iyy="1.98652847972192E-05"
        iyz="-9.66953808948319E-07"
        izz="0.000101234986556129" />
    </inertial>
    <visual>
      <origin
        xyz="0 0 0"
        rpy="0 0 0" />
      <geometry>
        <mesh
          filename="file://$(find pm_robot_description)/meshes/UV_Module_Left.STL" />
      </geometry>
<!--       <material
        name="">
        <color
          rgba="0.792156862745098 0.819607843137255 0.933333333333333 1" />
      </material> -->
    </visual>
    <collision>
      <origin
        xyz="0 0 0"
        rpy="0 0 0" />
      <geometry>
        <mesh
          filename="file://$(find pm_robot_description)/meshes/UV_Module_Left.STL" />
      </geometry>
    </collision>
  </link>
  <joint
    name="UV_Module_Left_Joint"
    type="prismatic">
    <origin
      xyz="0.109999999999999 0.0238200000000034 0.0276000000000078"
      rpy="0 0 0" />
    <parent
      link="UV_Cart_Left" />
    <child
      link="UV_Module_Left" />
    <axis
      xyz="0 1 0" />
    <limit
      lower="0.045"
      upper="0.045"
      effort="100"
      velocity="0.05" />
  </joint>
  <link
    name="UV_Cart_Right">
    <inertial>
      <origin
        xyz="0.110981633503817 -0.0370495599640397 0.0106949485927099"
        rpy="0 0 0" />
      <mass
        value="0.127959263593804" />
      <inertia
        ixx="5.21591452058585E-05"
        ixy="6.20383442649097E-08"
        ixz="1.12100820140438E-07"
        iyy="6.05583187268144E-05"
        iyz="-5.20562063181683E-08"
        izz="0.000108712758573194" />
    </inertial>
    <visual>
      <origin
        xyz="0 0 0"
        rpy="0 0 0" />
      <geometry>
        <mesh
          filename="file://$(find pm_robot_description)/meshes/UV_Cart_Right.STL" />
      </geometry>
<!--       <material
        name="">
        <color
          rgba="0.792156862745098 0.819607843137255 0.933333333333333 1" />
      </material> -->
    </visual>
    <collision>
      <origin
        xyz="0 0 0"
        rpy="0 0 0" />
      <geometry>
        <mesh
          filename="file://$(find pm_robot_description)/meshes/UV_Cart_Right.STL" />
      </geometry>
    </collision>
  </link>
  <joint
    name="UV_Cart_Right_Joint"
    type="prismatic">
    <origin
      xyz="0.00649999999276935 0.0511799999883173 0.252599999998818"
      rpy="0 0 0" />
    <parent
      link="Gonio_Base_Left" />
    <child
      link="UV_Cart_Right" />
    <axis
      xyz="1 0 0" />
    <limit
      lower="-0.045"
      upper="0.045"
      effort="0.05"
      velocity="100" />
  </joint>
  <link
    name="UV_Module_Right">
    <inertial>
      <origin
        xyz="0.00149625704165013 0.0198723785842292 0.0150907885908851"
        rpy="0 0 0" />
      <mass
        value="0.119915229322348" />
      <inertia
        ixx="8.58688560134346E-05"
        ixy="-9.33412693374251E-06"
        ixz="2.12947224034883E-07"
        iyy="1.98652847972198E-05"
        iyz="9.66953808948422E-07"
        izz="0.00010123498655613" />cls
    </inertial>
    <visual>
      <origin
        xyz="0 0 0"
        rpy="0 0 0" />
      <geometry>
        <mesh
          filename="file://$(find pm_robot_description)/meshes/UV_Module_Right.STL" />
      </geometry>
<!--       <material
        name="">
        <color
          rgba="0.792156862745098 0.819607843137255 0.933333333333333 1" />
      </material> -->
    </visual>
    <collision>
      <origin
        xyz="0 0 0"
        rpy="0 0 0" />
      <geometry>
        <mesh
          filename="file://$(find pm_robot_description)/meshes/UV_Module_Right.STL" />
      </geometry>
    </collision>
  </link>
  <joint
    name="UV_Module_Right_Joint"
    type="prismatic">
    <origin
      xyz="0.109999999941829 -0.0861800000000014 0.0276000000000078"
      rpy="0 0 0" />
    <parent
      link="UV_Cart_Right" />
    <child
      link="UV_Module_Right" />
    <axis
      xyz="0 -1 0" />
    <limit
      lower="0"
      upper="0.05"
      effort="100"
      velocity="0.05" />
  </joint>
</robot>
