<?xml version="1.0" encoding="utf-8"?>
<!-- This URDF was automatically created by SolidWorks to URDF Exporter! Originally created by Stephen Brawner (brawner@gmail.com) 
     Commit Version: 1.6.0-1-g15f4949  Build Version: 1.6.7594.29634
     For more information, please see http://wiki.ros.org/sw_urdf_exporter -->

<robot name="pm_robot_Gonio_Right">

<!--%%%%%%%%%%%%% Gonio_Right Definitions %%%%%%%%-->
  <link name="Gonio_Right">
    <inertial>
      <origin xyz="0.0449999999999999 0.0325 0.0840750321735946" rpy="0 0 0" />
      <mass value="0.735149712395274" />
      <inertia ixx="0.00216092025189497" ixy="-1.87538337450467E-19" ixz="3.93169924044221E-19" iyy="0.00218184071743384" iyz="-2.42183278976623E-19" izz="0.000537834506363752" />
    </inertial>
    <visual>
      <origin xyz="0 0 0" rpy="0 0 0" />
      <geometry>
        <mesh filename="file://$(find pm_robot_description)/meshes/Gonio_Right/Gonio_Right.STL" />
      </geometry>
    </visual>
    <collision>
      <origin xyz="0 0 0" rpy="0 0 0" />
      <geometry>
        <mesh filename="file://$(find pm_robot_description)/meshes/Gonio_Right/Gonio_Right.STL" />
      </geometry>
    </collision>
  </link>

  <joint name="Gonio_Right_Joint" type="fixed">
    <origin xyz="0.355 0.77 0.1127" rpy="0 0 0" />
    <parent link="base_link" />
    <child link="Gonio_Right" />
    <axis xyz="0 0 0" />
  </joint>

  <!--%%%%%%%%%%%%% Gonio_Right Stage Bottom Definitions-->
  <link name="Gonio_Right_Stage_1_Bottom">
    <inertial>
      <origin xyz="0.032500028562969 0.0154464744552945 0.0080287932266252" rpy="0 0 0" />
      <mass value="0.0706349432835735" />
      <inertia ixx="3.3696270673394E-05" ixy="-7.72258833163221E-11" ixz="-1.9198181347533E-11" iyy="1.8004068123271E-05" iyz="-1.39266767162837E-07" izz="4.86217530226209E-05" />
    </inertial>
    <visual>
      <origin xyz="0 0 0" rpy="0 0 0" />
      <geometry>
        <mesh filename="file://$(find pm_robot_description)/meshes/Gonio_Right/Gonio_Right_Stage_1_Bottom.STL" />
      </geometry>
    </visual>
    <collision>
      <origin xyz="0 0 0" rpy="0 0 0" />
      <geometry>
        <mesh filename="file://$(find pm_robot_description)/meshes/Gonio_Right/Gonio_Right_Stage_1_Bottom.STL" />
      </geometry>
    </collision>
  </link>
  <!---Gravity off-->
  <gazebo reference="Gonio_Right_Stage_1_Bottom">
    <turnGravityOff>true</turnGravityOff>
  </gazebo>

  <joint name="Gonio_Right_Stage_1_Bottom_Joint" type="fixed">
    <origin xyz="0.0125 0 0.172" rpy="0 0 0" />
    <parent link="Gonio_Right" />
    <child link="Gonio_Right_Stage_1_Bottom" />
    <axis xyz="0 0 0" />
  </joint>

  <!--%%%%%%%%%%%%% Gonio_Right Stage 1 Top Definitions-->
  <link name="Gonio_Right_Stage_1_Top">
    <inertial>
      <origin xyz="0.0236093539945057 -1.22301523672319E-07 -0.0788347959618205" rpy="0 0 0" />
      <mass value="0.13548582818363" />
      <inertia ixx="4.16210408086868E-05" ixy="8.20165430498813E-11" ixz="-1.10768531937264E-07" iyy="6.29207513367842E-05" iyz="3.62318914641735E-11" izz="9.71908514123069E-05" />
    </inertial>
    <visual>
      <origin xyz="0 0 0" rpy="0 0 0" />
      <geometry>
        <mesh filename="file://$(find pm_robot_description)/meshes/Gonio_Right/Gonio_Right_Stage_1_Top.STL" />
      </geometry>
    </visual>
    <collision>
      <origin xyz="0 0 0" rpy="0 0 0" />
      <geometry>
        <mesh filename="file://$(find pm_robot_description)/meshes/Gonio_Right/Gonio_Right_Stage_1_Top.STL" />
      </geometry>
    </collision>
  </link>
  <!---Gravity off-->
  <gazebo reference="Gonio_Right_Stage_1_Top">
    <turnGravityOff>true</turnGravityOff>
  </gazebo>

  <joint name="Gonio_Right_Stage_1_Top_Joint" type="revolute">
    <origin xyz="0 0.0325 0.11" rpy="0 0 0" />
    <parent link="Gonio_Right_Stage_1_Bottom" />
    <child link="Gonio_Right_Stage_1_Top" />
    <axis xyz="1 0 0" />
    <limit lower="-0.087266" upper="0.087266" effort="100" velocity="0.1" />
  </joint>

   <!--%%%%%%%%%%%%% Gonio_Right Stage 2 Bottom Definitions-->
  <link name="Gonio_Right_Stage_2_Bottom">
    <inertial>
      <origin xyz="-7.70699615237902E-10 -0.0325000008115904 -0.0578599597513434" rpy="0 0 0" />
      <mass value="0.0546397543064686" />
      <inertia ixx="2.38958828661972E-05" ixy="-1.02198811905052E-11" ixz="8.61195749809568E-13" iyy="1.83573872586573E-05" iyz="-3.0349864733646E-13" izz="3.9360874992296E-05" />
    </inertial>
    <visual>
      <origin xyz="0 0 0" rpy="0 0 0" />
      <geometry>
        <mesh filename="file://$(find pm_robot_description)/meshes/Gonio_Right/Gonio_Right_Stage_2_Bottom.STL" />
      </geometry>
    </visual>
    <collision>
      <origin xyz="0 0 0" rpy="0 0 0" />
      <geometry>
        <mesh filename="file://$(find pm_robot_description)/meshes/Gonio_Right/Gonio_Right_Stage_2_Bottom.STL" />
      </geometry>
    </collision>
  </link>

  <!---Gravity off-->
  <gazebo reference="Gonio_Right_Stage_2_Bottom">
    <turnGravityOff>true</turnGravityOff>
  </gazebo>

  <joint name="Gonio_Right_Stage_2_Bottom_Joint" type="revolute">
    <origin xyz="0.0325 0.0325 0" rpy="0 0 0" />
    <parent link="Gonio_Right_Stage_1_Top" />
    <child link="Gonio_Right_Stage_2_Bottom" />
    <axis xyz="0 -1 0" />
    <limit lower="-0.17453" upper="0.17453" effort="100" velocity="0.1" />
  </joint>

  <!--%%%%%%%%%%%%% Gonio Right Holder Definitions-->
  <link name="Gonio_Right_Chuck">
    <inertial>
      <origin xyz="0.0324508724608161 0.0324929107965058 0.0216564841336893" rpy="0 0 0" />
      <mass value="0.133934804202608" />
      <inertia ixx="3.05433990945279E-05" ixy="-2.55507616626323E-10" ixz="-1.74866993077662E-08" iyy="4.80787890381725E-05" iyz="2.24246430304669E-09" izz="7.18729232269435E-05" />
    </inertial>
    <visual>
      <origin xyz="0 0 0" rpy="0 0 0" />
      <geometry>
        <mesh filename="file://$(find pm_robot_description)/meshes/Gonio_Right/Gonio_Right_Chucks/Chuck_Siemens_UFC_Gonio_Right.STL" />
      </geometry>
    </visual>
    <collision>
      <origin xyz="0 0 0" rpy="0 0 0" />
      <geometry>
        <mesh filename="file://$(find pm_robot_description)/meshes/Gonio_Right/Gonio_Right_Chucks/Chuck_Siemens_UFC_Gonio_Right.STL" />
      </geometry>
    </collision>
  </link>

  <!---Gravity off-->
  <gazebo reference="Gonio_Right_Holder">
    <turnGravityOff>true</turnGravityOff>
  </gazebo>

  <joint name="Gonio_Right_Chuck_Joint" type="fixed">
    <origin xyz="-0.0325 -0.065 -0.05" rpy="0 0 0" />
    <parent link="Gonio_Right_Stage_2_Bottom" />
    <child link="Gonio_Right_Chuck" />
    <axis xyz="0 0 0" />
  </joint>

</robot> 