<?xml version="1.0" ?>
<!-- =================================================================================== -->
<!-- |    This document was autogenerated by xacro from pm_robot_main.xacro            | -->
<!-- |    EDITING THIS FILE BY HAND IS NOT RECOMMENDED                                 | -->
<!-- =================================================================================== -->
<robot name="pm_robot">
  <material name="black">
    <color rgba="0.0 0.0 0.0 1.0"/>
  </material>
  <material name="blue">
    <color rgba="0.0 0.0 0.8 1.0"/>
  </material>
  <material name="green">
    <color rgba="0.0 0.8 0.0 1.0"/>
  </material>
  <material name="grey">
    <color rgba="0.2 0.2 0.2 1.0"/>
  </material>
  <material name="orange">
    <color rgba="1.0 0.4235294117647059 0.0392156862745098 1.0"/>
  </material>
  <material name="brown">
    <color rgba="0.8705882352941177 0.8117647058823529 0.7647058823529411 1.0"/>
  </material>
  <material name="red">
    <color rgba="0.8 0.0 0.0 1.0"/>
  </material>
  <material name="white">
    <color rgba="1.0 1.0 1.0 1.0"/>
  </material>
  <material name="match_green">
    <color rgba="0.6901960784313725 0.796078431372549 0.12941176470588237 1"/>
  </material>
  <!--%%%%%%%%%%%%% Housing Definitions %%%%%%%%%%%%%-->
  <link name="housing_vl">
    <inertial>
      <origin rpy="0 0 0" xyz="0.106855071606918 -0.0365763858981578 0.4055"/>
      <mass value="15.7556351853533"/>
      <inertia ixx="0.894316439132711" ixy="0.0157593692116881" ixz="2.27661474248145E-18" iyy="0.894316439132711" iyz="-6.86930254496152E-17" izz="0.0614975233077981"/>
    </inertial>
    <visual>
      <origin rpy="0 0 0" xyz="0 0 0"/>
      <geometry>
        <mesh filename="file:///home/match-mover/Documents/ros2_ws/install/pm_robot_description/share/pm_robot_description/meshes/Housing/housing_vl.STL"/>
      </geometry>
      <material name="red"/>
    </visual>
    <collision>
      <origin rpy="0 0 0" xyz="0 0 0"/>
      <geometry>
        <mesh filename="file:///home/match-mover/Documents/ros2_ws/install/pm_robot_description/share/pm_robot_description/meshes/Housing/housing_vl.STL"/>
      </geometry>
    </collision>
  </link>
  <joint name="housing_vl_joint" type="fixed">
    <origin rpy="0 0 0" xyz="-0.198284271247462 -0.0548528137423858 0.11"/>
    <parent link="base_link_empthy"/>
    <child link="housing_vl"/>
    <axis xyz="0 0 0"/>
  </joint>
  <link name="housing_vr">
    <inertial>
      <origin rpy="0 0 0" xyz="0.0365763858981576 0.106855071606918 0.4055"/>
      <mass value="15.7556351853533"/>
      <inertia ixx="0.894316439132712" ixy="-0.0157593692116881" ixz="-2.21308886639773E-18" iyy="0.894316439132712" iyz="-6.04673492304204E-17" izz="0.0614975233077981"/>
    </inertial>
    <visual>
      <origin rpy="0 0 0" xyz="0 0 0"/>
      <geometry>
        <mesh filename="file:///home/match-mover/Documents/ros2_ws/install/pm_robot_description/share/pm_robot_description/meshes/Housing/housing_vr.STL"/>
      </geometry>
      <material name="red"/>
    </visual>
    <collision>
      <origin rpy="0 0 0" xyz="0 0 0"/>
      <geometry>
        <mesh filename="file:///home/match-mover/Documents/ros2_ws/install/pm_robot_description/share/pm_robot_description/meshes/Housing/housing_vr.STL"/>
      </geometry>
    </collision>
  </link>
  <joint name="housing_vr_joint" type="fixed">
    <origin rpy="0 0 0" xyz="1.25485281374239 -0.198284271247462 0.11"/>
    <parent link="base_link_empthy"/>
    <child link="housing_vr"/>
    <axis xyz="0 0 0"/>
  </joint>
  <link name="housing_hr">
    <inertial>
      <origin rpy="0 0 0" xyz="0.106855071606919 0.0365763858981576 -0.4055"/>
      <mass value="15.7556351853533"/>
      <inertia ixx="0.894316439132712" ixy="-0.015759369211688" ixz="3.2198946826335E-17" iyy="0.894316439132712" iyz="-8.14379058383444E-17" izz="0.0614975233077981"/>
    </inertial>
    <visual>
      <origin rpy="0 0 0" xyz="0 0 0"/>
      <geometry>
        <mesh filename="file:///home/match-mover/Documents/ros2_ws/install/pm_robot_description/share/pm_robot_description/meshes/Housing/housing_hr.STL"/>
      </geometry>
      <material name="red"/>
    </visual>
    <collision>
      <origin rpy="0 0 0" xyz="0 0 0"/>
      <geometry>
        <mesh filename="file:///home/match-mover/Documents/ros2_ws/install/pm_robot_description/share/pm_robot_description/meshes/Housing/housing_hr.STL"/>
      </geometry>
    </collision>
  </link>
  <joint name="housing_hr_joint" type="fixed">
    <origin rpy="-3.14159265358979 0 3.14159265358979" xyz="1.39828427124746 1.25485281374239 0.11"/>
    <parent link="base_link_empthy"/>
    <child link="housing_hr"/>
    <axis xyz="0 0 0"/>
  </joint>
  <link name="housing_hl">
    <inertial>
      <origin rpy="0 0 0" xyz="-0.0365763858981578 -0.106855071606918 0.4055"/>
      <mass value="15.7556351853533"/>
      <inertia ixx="0.894316439132711" ixy="-0.0157593692116881" ixz="-5.63429353481997E-18" iyy="0.894316439132711" iyz="-1.83506172989189E-16" izz="0.0614975233077981"/>
    </inertial>
    <visual>
      <origin rpy="0 0 0" xyz="0 0 0"/>
      <geometry>
        <mesh filename="file:///home/match-mover/Documents/ros2_ws/install/pm_robot_description/share/pm_robot_description/meshes/Housing/housing_hl.STL"/>
      </geometry>
      <material name="red"/>
    </visual>
    <collision>
      <origin rpy="0 0 0" xyz="0 0 0"/>
      <geometry>
        <mesh filename="file:///home/match-mover/Documents/ros2_ws/install/pm_robot_description/share/pm_robot_description/meshes/Housing/housing_hl.STL"/>
      </geometry>
    </collision>
  </link>
  <joint name="housing_hl_joint" type="fixed">
    <origin rpy="0 0 0" xyz="-0.0548528137423857 1.39828427124746 0.11"/>
    <parent link="base_link_empthy"/>
    <child link="housing_hl"/>
    <axis xyz="0 0 0"/>
  </joint>
  <link name="housing">
    <inertial>
      <origin rpy="0 0 0" xyz="0 0 0"/>
      <mass value="0"/>
      <inertia ixx="0" ixy="0" ixz="0" iyy="0" iyz="0" izz="0"/>
    </inertial>
    <visual>
      <origin rpy="0 0 0" xyz="0 0 0"/>
      <geometry>
        <mesh filename="file:///home/match-mover/Documents/ros2_ws/install/pm_robot_description/share/pm_robot_description/meshes/Housing/housing.STL"/>
      </geometry>
      <material name="grey"/>
    </visual>
    <collision>
      <origin rpy="0 0 0" xyz="0 0 0"/>
      <geometry>
        <mesh filename="file:///home/match-mover/Documents/ros2_ws/install/pm_robot_description/share/pm_robot_description/meshes/Housing/housing.STL"/>
      </geometry>
    </collision>
  </link>
  <joint name="housing_joint" type="fixed">
    <origin rpy="0 0 0" xyz="0 0 0"/>
    <parent link="base_link_empthy"/>
    <child link="housing"/>
    <axis xyz="0 0 0"/>
  </joint>
  <!-- <xacro:arg name="with_Gonio_Left" default="true" />
  <xacro:arg name="with_Gonio_Right" default="true" />
  <xacro:arg name="with_smarpod_station" default="false" /> -->
  <link name="world">
    </link>
  <joint name="world_joint" type="fixed">
    <parent link="world"/>
    <child link="base_link_empthy"/>
    <origin rpy="0 0 0" xyz="0 0 0"/>
  </joint>
  <!--%%%%%%%%%%%%% Base Link Definitions %%%%%%%%%%%%%-->
  <link name="base_link_empthy">
    </link>
  <!--%%%%%%%%%%%%% PM_Robot Base Link Definitions %%%%%%%%%%%%%-->
  <link name="pm_robot_base_link">
    <inertial>
      <origin rpy="0 0 0" xyz="0.600186355261373 0.60024822812755 -0.0500803495201262"/>
      <mass value="143.433412382625"/>
      <inertia ixx="17.331308476166" ixy="-0.000173857700061693" ixz="-0.00010330360577037" iyy="17.3263788236508" iyz="-0.00227792943650154" izz="34.4189883960519"/>
    </inertial>
    <visual>
      <origin rpy="0 0 0" xyz="0 0 0"/>
      <geometry>
        <mesh filename="file:///home/match-mover/Documents/ros2_ws/install/pm_robot_description/share/pm_robot_description/meshes/pm_robot_base_link.STL"/>
      </geometry>
      <material name="">
        <color rgba="1 1 1 1"/>
      </material>
    </visual>
    <collision>
      <origin rpy="0 0 0" xyz="0 0 0"/>
      <geometry>
        <mesh filename="file:///home/match-mover/Documents/ros2_ws/install/pm_robot_description/share/pm_robot_description/meshes/pm_robot_base_link.STL"/>
      </geometry>
    </collision>
  </link>
  <joint name="pm_robot_base_link_joint" type="fixed">
    <origin rpy="0 0 0" xyz="0 0 0.971"/>
    <parent link="base_link_empthy"/>
    <child link="pm_robot_base_link"/>
    <axis xyz="0 0 0"/>
  </joint>
  <link name="match_logo_link">
    </link>
  <joint name="match_logo_link_joint" type="fixed">
    <origin rpy="0 0 3.14159265359" xyz="1 -0.12 -0.09"/>
    <parent link="pm_robot_base_link"/>
    <child link="match_logo_link"/>
    <axis xyz="0 0 0"/>
  </joint>
  <link name="left_match_logo_background">
    <visual>
      <origin rpy="0 0 0" xyz="0 0 0"/>
      <geometry>
        <mesh filename="file:///home/match-mover/Documents/ros2_ws/install/pm_robot_description/share/pm_robot_description/meshes/Housing/match_background.dae" scale="0.001 0.001 0.001"/>
      </geometry>
      <material name="match_green"/>
    </visual>
    <collision>
      <origin rpy="0 0 0" xyz="0 0 0"/>
      <geometry>
        <mesh filename="file:///home/match-mover/Documents/ros2_ws/install/pm_robot_description/share/pm_robot_description/meshes/Housing/match_background.dae" scale="0.001 0.001 0.001"/>
      </geometry>
      <material name="match_green"/>
    </collision>
  </link>
  <joint name="left_match_logo_joint" type="fixed">
    <origin rpy="0 0 0" xyz="0 0 0"/>
    <parent link="match_logo_link"/>
    <child link="left_match_logo_background"/>
  </joint>
  <link name="left_match_logo_font">
    <visual>
      <origin rpy="1.5707963267948966 0 3.141592653589793" xyz="0 0 0 "/>
      <geometry>
        <mesh filename="file:///home/match-mover/Documents/ros2_ws/install/pm_robot_description/share/pm_robot_description/meshes/Housing/match_font.stl" scale="0.01 0.01 0.01"/>
      </geometry>
      <material name="white"/>
    </visual>
    <collision>
      <origin rpy="1.5707963267948966 0 3.141592653589793" xyz="0 0 0 "/>
      <geometry>
        <mesh filename="file:///home/match-mover/Documents/ros2_ws/install/pm_robot_description/share/pm_robot_description/meshes/Housing/match_font.stl" scale="0.01 0.01 0.01"/>
      </geometry>
      <material name="white"/>
    </collision>
  </link>
  <joint name="left_match_logo_font_joint" type="fixed">
    <origin rpy="0 0 0" xyz="0.042 0.0 -0.013"/>
    <parent link="left_match_logo_background"/>
    <child link="left_match_logo_font"/>
  </joint>
  <!--%%%%%%%%%%%%% Axis-Base Definitions %%%%%%%%%%%%%-->
  <link name="axis_base">
    <inertial>
      <origin rpy="0 0 0" xyz="0.396220059353836 0.105196690337481 0.307909602405796"/>
      <mass value="43.6102590245999"/>
      <inertia ixx="0.364950648797973" ixy="-0.000379121082023338" ixz="0.00337088160159615" iyy="2.29090638523672" iyz="0.000705385684699142" izz="2.23411883185999"/>
    </inertial>
    <visual>
      <origin rpy="0 0 0" xyz="0 0 0"/>
      <geometry>
        <mesh filename="file:///home/match-mover/Documents/ros2_ws/install/pm_robot_description/share/pm_robot_description/meshes/axis_base.STL"/>
      </geometry>
      <material name="grey"/>
    </visual>
    <collision>
      <origin rpy="0 0 0" xyz="0 0 0"/>
      <geometry>
        <mesh filename="file:///home/match-mover/Documents/ros2_ws/install/pm_robot_description/share/pm_robot_description/meshes/axis_base.STL"/>
      </geometry>
    </collision>
  </link>
  <joint name="axis_base_joint" type="fixed">
    <origin rpy="0 0 0" xyz="0.08001 0.632 1.000000000001E-05"/>
    <parent link="pm_robot_base_link"/>
    <child link="axis_base"/>
    <axis xyz="0 0 0"/>
  </joint>
  <!--%%%%%%%%%%%%% X Axis Definitions %%%%%%%%%%%%%-->
  <!-- Init Definition of 1K Dispenser tip -->
  <link name="X_Axis">
    <inertial>
      <origin rpy="0 0 0" xyz="0.13867117656886 0.0294673421865695 0.0322225410424505"/>
      <mass value="3.46651857022574"/>
      <inertia ixx="0.0263967056575219" ixy="-0.000746452162875097" ixz="-6.60103497268881E-06" iyy="0.0104790265642698" iyz="-0.000507544087069928" izz="0.0342327102580871"/>
    </inertial>
    <visual>
      <origin rpy="0 0 0" xyz="0 0 0"/>
      <geometry>
        <mesh filename="file:///home/match-mover/Documents/ros2_ws/install/pm_robot_description/share/pm_robot_description/meshes/X_Axis.STL"/>
      </geometry>
      <material name="orange"/>
    </visual>
    <collision>
      <origin rpy="0 0 0" xyz="0 0 0"/>
      <geometry>
        <mesh filename="file:///home/match-mover/Documents/ros2_ws/install/pm_robot_description/share/pm_robot_description/meshes/X_Axis.STL"/>
      </geometry>
    </collision>
  </link>
  <joint name="X_Axis_Joint" type="prismatic">
    <origin rpy="0 0 0" xyz="0.64699 0.11775 0.47499"/>
    <parent link="axis_base"/>
    <child link="X_Axis"/>
    <axis xyz="1 0 0"/>
    <limit effort="0.1" lower="-0.745" upper="0.05" velocity="35"/>
  </joint>
  <!--%%%%%%%%%%%%% Y Axis Definitions %%%%%%%%%%%%%-->
  <link name="Y_Axis">
    <inertial>
      <origin rpy="0 0 0" xyz="-0.00196813987548172 -0.3177998990051 0.113823941424653"/>
      <mass value="5.64847104935336"/>
      <inertia ixx="0.0734343917353869" ixy="-5.65230035141878E-06" ixz="-0.000161953758832679" iyy="0.0377139193260435" iyz="0.00720112978111611" izz="0.0598441739891415"/>
    </inertial>
    <visual>
      <origin rpy="0 0 0" xyz="0 0 0"/>
      <geometry>
        <mesh filename="file:///home/match-mover/Documents/ros2_ws/install/pm_robot_description/share/pm_robot_description/meshes/Y_Axis.STL"/>
      </geometry>
      <material name="brown"/>
    </visual>
    <collision>
      <origin rpy="0 0 0" xyz="0 0 0"/>
      <geometry>
        <mesh filename="file:///home/match-mover/Documents/ros2_ws/install/pm_robot_description/share/pm_robot_description/meshes/Y_Axis.STL"/>
      </geometry>
    </collision>
  </link>
  <joint name="Y_Axis_Joint" type="prismatic">
    <origin rpy="0 0 0" xyz="0.10865 0.25835 0.06525"/>
    <parent link="X_Axis"/>
    <child link="Y_Axis"/>
    <axis xyz="0 1 0"/>
    <limit effort="100" lower="-0.134000" upper="0.032400" velocity="35"/>
  </joint>
  <!--%%%%%%%%%%%%% Z Axis Definitions %%%%%%%%%%%%%-->
  <link name="Z_Axis">
    <inertial>
      <origin rpy="0 0 0" xyz="0.000627664293855634 -0.00434675424374531 -0.2726241124114"/>
      <mass value="2.64388477073549"/>
      <inertia ixx="0.0168607348742555" ixy="-1.50786678765243E-05" ixz="-0.000199875277453675" iyy="0.0218740034837586" iyz="-8.24046242568125E-05" izz="0.00606496678568248"/>
    </inertial>
    <visual>
      <origin rpy="0 0 0" xyz="0 0 0"/>
      <geometry>
        <mesh filename="file:///home/match-mover/Documents/ros2_ws/install/pm_robot_description/share/pm_robot_description/meshes/Z_Axis.STL"/>
      </geometry>
      <material name="blue"/>
    </visual>
    <collision>
      <origin rpy="0 0 0" xyz="0 0 0"/>
      <geometry>
        <mesh filename="file:///home/match-mover/Documents/ros2_ws/install/pm_robot_description/share/pm_robot_description/meshes/Z_Axis.STL"/>
      </geometry>
    </collision>
  </link>
  <!---Gravity off-->
  <gazebo reference="Z_Axis">
    <turnGravityOff>true</turnGravityOff>
  </gazebo>
  <joint name="Z_Axis_Joint" type="prismatic">
    <origin rpy="0 0 0" xyz="-0.00365 -0.499 0.28525"/>
    <parent link="Y_Axis"/>
    <child link="Z_Axis"/>
    <axis xyz="0 0 -1"/>
    <limit effort="100" lower="-0.0562" upper="0.041" velocity="35"/>
  </joint>
  <!--%%%%%%%%%%%%% T Axis Definitions %%%%%%%%%%%%%-->
  <link name="Gripper_Rot_Plate">
    <inertial>
      <origin rpy="0 0 0" xyz="-1.74281094778017E-07 2.03483659588777E-07 0.00907792340584457"/>
      <mass value="0.110297257842221"/>
      <inertia ixx="8.79759467929701E-05" ixy="1.90651210379881E-6" ixz="1.25536613370482E-6" iyy="8.79764882626525E-05" iyz="-1.50065581017382E-6" izz="0.00016565987032676"/>
    </inertial>
    <visual>
      <origin rpy="0 0 0" xyz="0 0 0"/>
      <geometry>
        <mesh filename="file:///home/match-mover/Documents/ros2_ws/install/pm_robot_description/share/pm_robot_description/meshes/Gripper_Rot_Plate.STL"/>
      </geometry>
      <material name="black"/>
    </visual>
    <collision>
      <origin rpy="0 0 0" xyz="0 0 0"/>
      <geometry>
        <mesh filename="file:///home/match-mover/Documents/ros2_ws/install/pm_robot_description/share/pm_robot_description/meshes/Gripper_Rot_Plate.STL"/>
      </geometry>
    </collision>
  </link>
  <!---Gravity off-->
  <gazebo reference="Gripper_Rot_Plate">
    <turnGravityOff>true</turnGravityOff>
  </gazebo>
  <joint name="T_Axis_Joint" type="revolute">
    <origin rpy="0 0 0" xyz="0.0600000000000017 -0.0580000000000003 -0.427500000000004"/>
    <parent link="Z_Axis"/>
    <child link="Gripper_Rot_Plate"/>
    <axis xyz="0 0 1"/>
    <limit effort="100" lower="-2.0" upper="2.0" velocity="5"/>
  </joint>
  <link name="t_axis_toolchanger">
    <inertial>
      <origin rpy="0 0 0" xyz="2.66657822625138E-05 -6.51697797860451E-05 -0.0173989628147272"/>
      <mass value="0.0741175653990944"/>
      <inertia ixx="1.38724675369177E-05" ixy="-2.81065278601148E-08" ixz="-4.32931581160332E-09" iyy="1.28173377099281E-05" iyz="-3.69738102041932E-6" izz="2.32495071670115E-05"/>
    </inertial>
    <visual>
      <origin rpy="0 0 0" xyz="0 0 0"/>
      <geometry>
        <mesh filename="file:///home/match-mover/Documents/ros2_ws/install/pm_robot_description/share/pm_robot_description/meshes/t_axis_tool.STL"/>
      </geometry>
      <material name="">
        <color rgba="0.75294 0.75294 0.75294 1"/>
      </material>
    </visual>
    <collision>
      <origin rpy="0 0 0" xyz="0 0 0"/>
      <geometry>
        <mesh filename="file:///home/match-mover/Documents/ros2_ws/install/pm_robot_description/share/pm_robot_description/meshes/t_axis_tool.STL"/>
      </geometry>
    </collision>
  </link>
  <!---Gravity off-->
  <gazebo reference="t_axis_toolchanger">
    <turnGravityOff>true</turnGravityOff>
  </gazebo>
  <joint name="t_axis_toolchanger_joint" type="fixed">
    <origin rpy="0 0 0" xyz="0 0 0"/>
    <parent link="Gripper_Rot_Plate"/>
    <child link="t_axis_toolchanger"/>
    <axis xyz="0 0 0"/>
  </joint>
  <!-- 

    This link is now defined in the individual gripper files
    <link name="PM_Robot_Tool_TCP">
    </link>

    <xacro:property name="PM_Robot_Tool_TCP_Joint_Cal_x" value="${calibration_dict['PM_Robot_Tool_TCP_Joint']['x_offset']}"/>
    <xacro:property name="PM_Robot_Tool_TCP_Joint_Cal_y" value="${calibration_dict['PM_Robot_Tool_TCP_Joint']['y_offset']}"/>
    <xacro:property name="PM_Robot_Tool_TCP_Joint_Cal_z" value="${calibration_dict['PM_Robot_Tool_TCP_Joint']['z_offset']}"/>
    <xacro:property name="PM_Robot_Tool_TCP_Joint_Cal_rx" value="${calibration_dict['PM_Robot_Tool_TCP_Joint']['rx_offset']}"/>
    <xacro:property name="PM_Robot_Tool_TCP_Joint_Cal_ry" value="${calibration_dict['PM_Robot_Tool_TCP_Joint']['ry_offset']}"/>
    <xacro:property name="PM_Robot_Tool_TCP_Joint_Cal_rz" value="${calibration_dict['PM_Robot_Tool_TCP_Joint']['rz_offset']}"/>

    <xacro:property name="pm_robot_tool_TCP_z_offset" value="$(arg pm_robot_tool_TCP_z_offset)"/>

    <joint name="PM_Robot_Tool_TCP_Joint" type="fixed">
      Hier spaeter Variable
      <origin xyz="
        ${0 + PM_Robot_Tool_TCP_Joint_Cal_x * 0.000001} 
        ${0 + PM_Robot_Tool_TCP_Joint_Cal_y * 0.000001} 
        ${0 + pm_robot_tool_TCP_z_offset + PM_Robot_Tool_TCP_Joint_Cal_z * 0.000001}" rpy="
        ${0 + PM_Robot_Tool_TCP_Joint_Cal_rx * 3.14159265359/180} 
        ${0 + PM_Robot_Tool_TCP_Joint_Cal_ry * 3.14159265359/180} 
        ${0 + PM_Robot_Tool_TCP_Joint_Cal_rz * 3.14159265359/180}" />
      <parent link="Gripper_Rot_Plate" />
      <child link="PM_Robot_Tool_TCP" />
      <axis xyz="0 0 0" />
    </joint> -->
  <!--%%%%%%%%%%%%% 1K Dispenser Flap Definitions %%%%%%%%%%%%%-->
  <link name="1K_Dispenser_Flap">
    <inertial>
      <origin rpy="0 0 0" xyz="-0.0475534171935499 -0.0152444446246764 -0.0129366605877314"/>
      <mass value="0.0179075605864254"/>
      <inertia ixx="4.17413884237766E-06" ixy="1.29835566651944E-07" ixz="6.2953731666034E-08" iyy="5.03313568637311E-06" iyz="9.02306176060272E-09" izz="4.11882542880041E-06"/>
    </inertial>
    <visual>
      <origin rpy="0 0 0" xyz="0 0 0"/>
      <geometry>
        <mesh filename="file:///home/match-mover/Documents/ros2_ws/install/pm_robot_description/share/pm_robot_description/meshes/Glue_Cartridge_Flap.STL"/>
      </geometry>
      <material name="white"/>
    </visual>
    <collision>
      <origin rpy="0 0 0" xyz="0 0 0"/>
      <geometry>
        <mesh filename="file:///home/match-mover/Documents/ros2_ws/install/pm_robot_description/share/pm_robot_description/meshes/Glue_Cartridge_Flap.STL"/>
      </geometry>
    </collision>
  </link>
  <!---Gravity off-->
  <gazebo reference="1K_Dispenser_Flap">
    <turnGravityOff>true</turnGravityOff>
  </gazebo>
  <joint name="1K_Dispenser_Flap_Joint" type="prismatic">
    <origin rpy="0 0 0" xyz="-0.0315 -0.02479 -0.424"/>
    <parent link="Z_Axis"/>
    <child link="1K_Dispenser_Flap"/>
    <axis xyz="-1 0 0"/>
    <limit effort="100" lower="-0.025" upper="0.00" velocity="0.5"/>
  </joint>
  <!--%%%%%%%%%%%%% 1K Dispenser Definitions %%%%%%%%%%%%%-->
  <link name="1K_Dispenser">
    <inertial>
      <origin rpy="0 0 0" xyz="-0.00291125760198996 -0.0158910684396169 -0.0486744620635529"/>
      <mass value="0.0741292037954837"/>
      <inertia ixx="3.4337175367919E-05" ixy="-1.91908706800505E-07" ixz="-5.62664674872138E-08" iyy="3.41011193217523E-05" iyz="5.66364181173195E-07" izz="1.14904781429849E-05"/>
    </inertial>
    <visual>
      <origin rpy="0 0 0" xyz="0 0 0"/>
      <geometry>
        <mesh filename="file:///home/match-mover/Documents/ros2_ws/install/pm_robot_description/share/pm_robot_description/meshes/1K_Dispenser.STL"/>
      </geometry>
      <material name="grey"/>
    </visual>
    <collision>
      <origin rpy="0 0 0" xyz="0 0 0"/>
      <geometry>
        <mesh filename="file:///home/match-mover/Documents/ros2_ws/install/pm_robot_description/share/pm_robot_description/meshes/1K_Dispenser.STL"/>
      </geometry>
    </collision>
  </link>
  <!---Gravity off-->
  <gazebo reference="1K_Dispenser">
    <turnGravityOff>true</turnGravityOff>
  </gazebo>
  <joint name="1K_Dispenser_Joint" type="prismatic">
    <origin rpy="0 0 0" xyz="-0.104 -0.0262 -0.3545"/>
    <parent link="Z_Axis"/>
    <child link="1K_Dispenser"/>
    <axis xyz="0 0 -1"/>
    <limit effort="100" lower="0" upper="0.04" velocity="0.05"/>
  </joint>
  <link name="1K_Dispenser_TCP">
    </link>
  <joint name="1K_Dispenser_TCP_Joint" type="fixed">
    <origin rpy="         0.0          0.0          0.0" xyz="         -0.001          -0.0318          -0.1223"/>
    <parent link="1K_Dispenser"/>
    <child link="1K_Dispenser_TCP"/>
    <axis xyz="0 0 0"/>
  </joint>
  <!--%%%%%%%%%%%%% The parameters here are interchangeable %%%%%%%%%%%%%-->
  <!--%%%%%%%%%%%%% Jaw 1 Definitions %%%%%%%%%%%%%-->
  <link name="1K_Dispenser_Tip">
    <inertial>
      <origin rpy="0 0 0" xyz="-3.29882314770198E-12 -2.87859854641722E-08 0.0233706132060024"/>
      <mass value="0.00266749600701752"/>
      <inertia ixx="0.0734343917353869" ixy="-5.65230035141878e-06" ixz="-0.000161953758832679" iyy="0.0377139193260435" iyz="0.00720112978111611" izz="0.0598441739891415"/>
    </inertial>
    <visual>
      <origin rpy="0 0 0" xyz="0 0 0"/>
      <geometry>
        <mesh filename="file:///home/match-mover/Documents/ros2_ws/install/pm_robot_description/share/pm_robot_description/meshes/Dispenser_Tips/Dis_Tip_Red_I_250_A520_L12700.STL"/>
      </geometry>
      <material name="red">
        </material>
    </visual>
    <collision>
      <origin rpy="0 0 0" xyz="0 0 0"/>
      <geometry>
        <mesh filename="file:///home/match-mover/Documents/ros2_ws/install/pm_robot_description/share/pm_robot_description/meshes/Dispenser_Tips/Dis_Tip_Red_I_250_A520_L12700.STL"/>
      </geometry>
    </collision>
  </link>
  <gazebo reference="1K_Dispenser_Tip">
    <turnGravityOff>true</turnGravityOff>
  </gazebo>
  <joint name="1K_Dispenser_Tip_Joint" type="fixed">
    <!-- This needs to be corrected in Solidworks -->
    <origin rpy="0 0 0" xyz="0.000 0 0 "/>
    <parent link="1K_Dispenser_TCP"/>
    <child link="1K_Dispenser_Tip"/>
  </joint>
  <!--%%%%%%%%%%%%% 2K Dispenser Definitions-->
  <link name="2K_Dispenser_Cartridge">
    <inertial>
      <origin rpy="0 0 0" xyz="0.000286904622212703 -0.0363382955214142 0.157114812049142"/>
      <mass value="0.410111177184055"/>
      <inertia ixx="0.00156205497813664" ixy="-4.41612447012715E-06" ixz="-9.93222982118684E-08" iyy="0.00154767600658026" iyz="-1.49654417442962E-06" izz="0.000122541965999881"/>
    </inertial>
    <visual>
      <origin rpy="0 0 0" xyz="0 0 0"/>
      <geometry>
        <mesh filename="file:///home/match-mover/Documents/ros2_ws/install/pm_robot_description/share/pm_robot_description/meshes/2K_Glue_Cartridge.STL"/>
      </geometry>
      <material name="white"/>
    </visual>
    <collision>
      <origin rpy="0 0 0" xyz="0 0 0"/>
      <geometry>
        <mesh filename="file:///home/match-mover/Documents/ros2_ws/install/pm_robot_description/share/pm_robot_description/meshes/2K_Glue_Cartridge.STL"/>
      </geometry>
    </collision>
  </link>
  <!---Gravity off-->
  <gazebo reference="2K_Dispenser_Cartridge">
    <turnGravityOff>true</turnGravityOff>
  </gazebo>
  <joint name="2K_Dispenser_Joint" type="prismatic">
    <origin rpy="0 0 0" xyz="-0.169 0.01176 -0.424"/>
    <parent link="Z_Axis"/>
    <child link="2K_Dispenser_Cartridge"/>
    <axis xyz="0 0 1"/>
    <limit effort="100" lower="-0.04" upper="0.00" velocity="0.1"/>
  </joint>
  <link name="2K_Dispenser_TCP">
    </link>
  <joint name="2K_Dispenser_TCP_Joint" type="fixed">
    <origin rpy="         0.0          0.0          0.0" xyz="         0.0          -0.045          -0.04614"/>
    <parent link="2K_Dispenser_Cartridge"/>
    <child link="2K_Dispenser_TCP"/>
    <axis xyz="0 0 0"/>
  </joint>
  <!--%%%%%%%%%%%%% Top Camera Definitions-->
  <link name="Cam1_Toolhead_TCP">
    <inertial>
      <origin rpy="0 0 0" xyz="0.00294756628931103 0.0112908552453015 0.186544370768599"/>
      <mass value="0.222202026755256"/>
      <inertia ixx="0.000198536268283264" ixy="-2.57443493637635E-07" ixz="-2.33028260890714E-06" iyy="0.00020443076967091" iyz="-8.54446341843522E-06" izz="4.76896342979841E-05"/>
    </inertial>
    <visual>
      <origin rpy="0 0 0" xyz="0 0 0"/>
      <geometry>
        <mesh filename="file:///home/match-mover/Documents/ros2_ws/install/pm_robot_description/share/pm_robot_description/meshes/Cam1_Toolhead_TCP.STL"/>
      </geometry>
      <material name="">
        <color rgba="0.752941176470588 0.752941176470588 0.752941176470588 1"/>
      </material>
    </visual>
    <collision>
      <origin rpy="0 0 0" xyz="0 0 0"/>
      <geometry>
        <mesh filename="file:///home/match-mover/Documents/ros2_ws/install/pm_robot_description/share/pm_robot_description/meshes/Cam1_Toolhead_TCP.STL"/>
      </geometry>
    </collision>
  </link>
  <!---Gravity off-->
  <gazebo reference="Cam1_Toolhead_TCP">
    <turnGravityOff>true</turnGravityOff>
  </gazebo>
  <joint name="Cam1_Toolhead_TCP_Joint" type="fixed">
    <origin rpy="         0.0          0.0          0.0" xyz="         -0.0320000000000003          -0.0579999999999998          -0.515338706"/>
    <parent link="Z_Axis"/>
    <child link="Cam1_Toolhead_TCP"/>
    <axis xyz="0 0 0"/>
  </joint>
  <!--%%%%%%%%%%%%% Laser Toolhead Definitions-->
  <link name="Laser_Toolhead_TCP">
    <inertial>
      <origin rpy="0 0 0" xyz="0.00143426339843722 0.014826109459576 0.0588947661972293"/>
      <mass value="0.185632781644417"/>
      <inertia ixx="0.00018384097226268" ixy="5.39428478530615E-09" ixz="-6.26322611599089E-07" iyy="0.000136967759808617" iyz="6.13082513214026E-07" izz="7.65210217467237E-05"/>
    </inertial>
    <visual>
      <origin rpy="0 0 0" xyz="0 0 0"/>
      <geometry>
        <mesh filename="file:///home/match-mover/Documents/ros2_ws/install/pm_robot_description/share/pm_robot_description/meshes/Laser_Kopf_TCP.STL"/>
      </geometry>
      <material name="">
        <color rgba="0.752941176470588 0.752941176470588 0.752941176470588 1"/>
      </material>
    </visual>
    <collision>
      <origin rpy="0 0 0" xyz="0 0 0"/>
      <geometry>
        <mesh filename="file:///home/match-mover/Documents/ros2_ws/install/pm_robot_description/share/pm_robot_description/meshes/Laser_Kopf_TCP.STL"/>
      </geometry>
    </collision>
  </link>
  <!---Gravity off-->
  <gazebo reference="Laser_Toolhead_TCP">
    <turnGravityOff>true</turnGravityOff>
  </gazebo>
  <joint name="Laser_Toolhead_TCP_Joint" type="fixed">
    <origin rpy="           0.0            0.0            0.0" xyz="           0.147498952947694            -0.0739999732334102            -0.495500146516092"/>
    <parent link="Z_Axis"/>
    <child link="Laser_Toolhead_TCP"/>
    <axis xyz="0 0 0"/>
  </joint>
  <!--%%%%%%%%%%%%% Test Station Definitions-->
  <link name="Test_Station">
    <inertial>
      <origin rpy="0 0 0" xyz="0.0250000000000002 0.0791274046351475 -0.154851137332961"/>
      <mass value="1.39099524679326"/>
      <inertia ixx="0.00780193904512034" ixy="-2.61717009512019E-6" ixz="-4.79910370720457E-6" iyy="0.00547600691976027" iyz="9.87499782602546E-6" izz="0.00281708795214926"/>
    </inertial>
    <visual>
      <origin rpy="0 0 0" xyz="0 0 0"/>
      <geometry>
        <mesh filename="file:///home/match-mover/Documents/ros2_ws/install/pm_robot_description/share/pm_robot_description/meshes/Test_Station.STL"/>
      </geometry>
      <material name="white"/>
    </visual>
    <collision>
      <origin rpy="0 0 0" xyz="0 0 0"/>
      <geometry>
        <mesh filename="file:///home/match-mover/Documents/ros2_ws/install/pm_robot_description/share/pm_robot_description/meshes/Test_Station.STL"/>
      </geometry>
    </collision>
  </link>
  <joint name="Test_Station_Joint" type="fixed">
    <origin rpy="0 0 0" xyz="0.075 0.3265 0.298"/>
    <parent link="pm_robot_base_link"/>
    <child link="Test_Station"/>
    <axis xyz="0 0 0"/>
  </joint>
  <!--%%%%%%%%%%%%% Camera Station Definitions-->
  <link name="Camera_Station">
    <inertial>
      <origin rpy="0 0 0" xyz="0.0886413519365855 0.189925462464436 0.138483690350839"/>
      <mass value="2.70231148841738"/>
      <inertia ixx="0.0183035942970588" ixy="1.26351026901094E-05" ixz="-2.79575355635167E-06" iyy="0.00441812287973743" iyz="5.22848888698871E-05" izz="0.0193956330708548"/>
    </inertial>
    <visual>
      <origin rpy="0 0 0" xyz="0 0 0"/>
      <geometry>
        <mesh filename="file:///home/match-mover/Documents/ros2_ws/install/pm_robot_description/share/pm_robot_description/meshes/Camera_Station.STL"/>
      </geometry>
      <material name="white"/>
    </visual>
    <collision>
      <origin rpy="0 0 0" xyz="0 0 0"/>
      <geometry>
        <mesh filename="file:///home/match-mover/Documents/ros2_ws/install/pm_robot_description/share/pm_robot_description/meshes/Camera_Station.STL"/>
      </geometry>
    </collision>
  </link>
  <joint name="Camera_Station_Joint" type="fixed">
    <origin rpy="0 0 0" xyz="0.4525 0.3125 0"/>
    <parent link="pm_robot_base_link"/>
    <child link="Camera_Station"/>
    <axis xyz="0 0 0"/>
  </joint>
  <link name="Camera_Station_TCP">
    </link>
  <joint name="Camera_Station_TCP_Joint" type="fixed">
    <origin rpy="         0.0          0.0          0.0" xyz="         0.08          0.092783          0.3045"/>
    <parent link="Camera_Station"/>
    <child link="Camera_Station_TCP"/>
    <axis xyz="0 0 0"/>
  </joint>
  <!--%%%%%%%%%%%%% Camera Calibration Definitions-->
  <link name="Camera_Calibration_Platelet">
    <inertial>
      <origin rpy="0 0 0" xyz="-0.000344499007125409 0.0696122748122424 0.000295151280628292"/>
      <mass value="0.0334016358510876"/>
      <inertia ixx="2.05104945364406E-05" ixy="-1.61006130053269E-08" ixz="-7.42638002033627E-6" iyy="2.64967112268826E-06" iyz="4.64472618194223E-07" izz="2.23824646029018E-05"/>
    </inertial>
    <visual>
      <origin rpy="0 0 0" xyz="0 0 0"/>
      <geometry>
        <mesh filename="file:///home/match-mover/Documents/ros2_ws/install/pm_robot_description/share/pm_robot_description/meshes/Camera_Calibration_Platelet.STL"/>
      </geometry>
      <material name="green"/>
    </visual>
    <collision>
      <origin rpy="0 0 0" xyz="0 0 0"/>
      <geometry>
        <mesh filename="file:///home/match-mover/Documents/ros2_ws/install/pm_robot_description/share/pm_robot_description/meshes/Camera_Calibration_Platelet.STL"/>
      </geometry>
    </collision>
  </link>
  <joint name="Camera_Calibration_Platelet_Joint" type="prismatic">
    <origin rpy="0 0 0" xyz="0.08 -0.0805 0.293"/>
    <parent link="Camera_Station"/>
    <child link="Camera_Calibration_Platelet"/>
    <axis xyz="0 -1 0"/>
    <limit effort="100" lower="-0.04" upper="0.0" velocity="0.5"/>
  </joint>
  <!--%%%%%%%%%%%%% Calibration Qube Definitions-->
  <link name="Calibration_Qube">
    <inertial>
      <origin rpy="0 0 0" xyz="0 -5.55111512312578E-6 -0.007418215969486"/>
      <mass value="0.000608132735199849"/>
      <inertia ixx="3.05434929012605E-04" ixy="2.70098962651108E-6" ixz="-1.09265340380468E-6" iyy="3.05434929012605E-04" iyz="6.45610037231024E-6" izz="5.52989859299796E-04"/>
    </inertial>
    <visual>
      <origin rpy="0 0 0" xyz="0 0 0"/>
      <geometry>
        <mesh filename="file:///home/match-mover/Documents/ros2_ws/install/pm_robot_description/share/pm_robot_description/meshes/Calibration_Qube.STL"/>
      </geometry>
      <material name="green"/>
    </visual>
    <collision>
      <origin rpy="0 0 0" xyz="0 0 0"/>
      <geometry>
        <mesh filename="file:///home/match-mover/Documents/ros2_ws/install/pm_robot_description/share/pm_robot_description/meshes/Calibration_Qube.STL"/>
      </geometry>
    </collision>
  </link>
  <!---Gravity off-->
  <gazebo reference="Calibration_Qube">
    <turnGravityOff>true</turnGravityOff>
  </gazebo>
  <joint name="Calibration_Qube_Joint" type="prismatic">
    <origin rpy="           0.0            0.0            0.0" xyz="           0.154            0.108            0.305"/>
    <parent link="Camera_Station"/>
    <child link="Calibration_Qube"/>
    <axis xyz="0 0 1"/>
    <limit effort="0" lower="-0.008" upper="0" velocity="0.005"/>
  </joint>
  <!-- START - Loading Config Files-->
  <!-- END - Loading Config Files-->
  <!-- START - Tool Defines-->
  <link name="PM_Robot_Vacuum_Tool">
    <inertial>
      <origin rpy="0 0 0" xyz="-5.23913406004772E-05 3.02196159816615E-05 0.0222290213656595"/>
      <mass value="0.0172841989183379"/>
      <inertia ixx="0.0734343917353869" ixy="-5.65230035141878e-06" ixz="-0.000161953758832679" iyy="0.0377139193260435" iyz="0.00720112978111611" izz="0.0598441739891415"/>
    </inertial>
    <visual>
      <origin rpy="0 0 0" xyz="0 0 0"/>
      <geometry>
        <mesh filename="file:///home/match-mover/Documents/ros2_ws/install/pm_robot_description/share/pm_robot_description/meshes/Tools/Schunk_Vacuum_Tools/SPT_Toolholder/Tool_Schunk_SPT_Holder.STL"/>
      </geometry>
      <material name="grey">
      </material>
    </visual>
    <collision>
      <origin rpy="0 0 0" xyz="0 0 0"/>
      <geometry>
        <mesh filename="file:///home/match-mover/Documents/ros2_ws/install/pm_robot_description/share/pm_robot_description/meshes/Tools/Schunk_Vacuum_Tools/SPT_Toolholder/Tool_Schunk_SPT_Holder.STL"/>
      </geometry>
    </collision>
  </link>
  <!---Gravity off-->
  <gazebo reference="PM_Robot_Vacuum_Tool">
    <turnGravityOff>true</turnGravityOff>
    <color>1.0 0 0.5 1.0</color>
  </gazebo>
  <joint name="PM_Robot_Vacuum_Tool_Joint" type="fixed">
    <origin rpy="0 0 0" xyz="0 0 0"/>
    <parent link="PM_Robot_Tool_TCP"/>
    <child link="PM_Robot_Vacuum_Tool"/>
    <axis xyz="0 0 0"/>
  </joint>
  <link name="PM_Robot_Vacuum_Tool_Tip">
    <inertial>
      <origin rpy="0 0 0" xyz="0 0 0.00881061215391388"/>
      <mass value="0.00106303297474693"/>
      <inertia ixx="0.0734343917353869" ixy="-5.65230035141878e-06" ixz="-0.000161953758832679" iyy="0.0377139193260435" iyz="0.00720112978111611" izz="0.0598441739891415"/>
    </inertial>
    <visual>
      <origin rpy="0 0 0" xyz="0 0 0"/>
      <geometry>
        <mesh filename="file:///home/match-mover/Documents/ros2_ws/install/pm_robot_description/share/pm_robot_description/meshes/Tools/Schunk_Vacuum_Tools/SPT_Toolholder/Tips/Tool_Tip_R_A1000_I500.STL"/>
      </geometry>
      <material name="white">
      </material>
    </visual>
    <collision>
      <origin rpy="0 0 0" xyz="0 0 0"/>
      <geometry>
        <mesh filename="file:///home/match-mover/Documents/ros2_ws/install/pm_robot_description/share/pm_robot_description/meshes/Tools/Schunk_Vacuum_Tools/SPT_Toolholder/Tips/Tool_Tip_R_A1000_I500.STL"/>
      </geometry>
    </collision>
  </link>
  <!---Gravity off-->
  <gazebo reference="PM_Robot_Vacuum_Tool_Tip">
    <turnGravityOff>true</turnGravityOff>
    <color>1.0 0 0.5 1.0</color>
  </gazebo>
  <joint name="PM_Robot_Vacuum_Tool_Tip_Joint" type="fixed">
    <origin rpy="0 0 0" xyz="0 0 0"/>
    <parent link="PM_Robot_Tool_TCP"/>
    <child link="PM_Robot_Vacuum_Tool_Tip"/>
    <axis xyz="0 0 0"/>
  </joint>
  <link name="PM_Robot_Tool_TCP">
  </link>
  <joint name="PM_Robot_Tool_TCP_Joint" type="fixed">
    <origin rpy="       0.0        0.0        0.0" xyz="       0.0        0.0        -0.07442"/>
    <parent link="Gripper_Rot_Plate"/>
    <child link="PM_Robot_Tool_TCP"/>
    <axis xyz="0 0 0"/>
  </joint>
  <!-- END - Tool Defines-->
  <!-- START - Gonio Defines-->
  <!--%%%%%%%%%%%%% Gonio_Right Definitions %%%%%%%%-->
  <link name="Gonio_Base_Right">
    <inertial>
      <origin rpy="0 0 0" xyz="0.0750000000000001 0.0875 0.0967750321735945"/>
      <mass value="0.735149712395275"/>
      <inertia ixx="0.00216092025189497" ixy="-1.14771309991733E-20" ixz="-3.69522069861046E-19" iyy="0.00218184071743384" iyz="5.29016162077308E-20" izz="0.000537834506363752"/>
    </inertial>
    <visual>
      <origin rpy="0 0 0" xyz="0 0 0"/>
      <geometry>
        <mesh filename="file:///home/match-mover/Documents/ros2_ws/install/pm_robot_description/share/pm_robot_description/meshes/Gonio_Right/Gonio_Base_Right.STL"/>
      </geometry>
      <material name="white"/>
    </visual>
    <collision>
      <origin rpy="0 0 0" xyz="0 0 0"/>
      <geometry>
        <mesh filename="file:///home/match-mover/Documents/ros2_ws/install/pm_robot_description/share/pm_robot_description/meshes/Gonio_Right/Gonio_Base_Right.STL"/>
      </geometry>
    </collision>
  </link>
  <joint name="Gonio_Base_Right_Joint" type="fixed">
    <origin rpy="0 0 0" xyz="0.750000000000003 0.31 0"/>
    <parent link="pm_robot_base_link"/>
    <child link="Gonio_Base_Right"/>
    <axis xyz="0 0 0"/>
  </joint>
  <!--%%%%%%%%%%%%% Gonio_Right Stage Bottom Definitions-->
  <link name="Gonio_Right_Stage_1_Bottom">
    <inertial>
      <origin rpy="0 0 0" xyz="0.0473956245440273 0.0326775285629692 0.00802879322662528"/>
      <mass value="0.0706349432835732"/>
      <inertia ixx="1.8004068123271E-05" ixy="7.72258833076008E-11" ixz="1.39266767162876E-07" iyy="3.36962706733938E-05" iyz="-1.91981813996212E-11" izz="4.86217530226206E-05"/>
    </inertial>
    <visual>
      <origin rpy="0 0 0" xyz="0 0 0"/>
      <geometry>
        <mesh filename="file:///home/match-mover/Documents/ros2_ws/install/pm_robot_description/share/pm_robot_description/meshes/Gonio_Right/Gonio_Right_Stage_1.STL"/>
      </geometry>
      <material name="grey"/>
    </visual>
    <collision>
      <origin rpy="0 0 0" xyz="0 0 0"/>
      <geometry>
        <mesh filename="file:///home/match-mover/Documents/ros2_ws/install/pm_robot_description/share/pm_robot_description/meshes/Gonio_Right/Gonio_Right_Stage_1.STL"/>
      </geometry>
    </collision>
  </link>
  <!---Gravity off-->
  <gazebo reference="Gonio_Right_Stage_1_Bottom">
    <turnGravityOff>true</turnGravityOff>
  </gazebo>
  <joint name="Gonio_Right_Stage_1_Bottom_Joint" type="fixed">
    <origin rpy="0 0 0" xyz="0.0425000000000001 0.055 0.1847"/>
    <parent link="Gonio_Base_Right"/>
    <child link="Gonio_Right_Stage_1_Bottom"/>
    <axis xyz="0 0 0"/>
  </joint>
  <!--%%%%%%%%%%%%% Gonio_Right Stage 1 Top Definitions-->
  <link name="Gonio_Right_Stage_1_Top">
    <inertial>
      <origin rpy="0 0 0" xyz="-1.23867349599571E-07 0.00776563461425855 -0.0788347959618214"/>
      <mass value="0.135485828183631"/>
      <inertia ixx="6.29207513367842E-05" ixy="-8.20165428667741E-11" ixz="3.32779841696372E-11" iyy="4.16210408086872E-05" iyz="1.10769519244758E-07" izz="9.7190851412307E-05"/>
    </inertial>
    <visual>
      <origin rpy="0 0 0" xyz="0 0 0"/>
      <geometry>
        <mesh filename="file:///home/match-mover/Documents/ros2_ws/install/pm_robot_description/share/pm_robot_description/meshes/Gonio_Right/Gonio_Right_Stage_1_Upper.STL"/>
      </geometry>
      <material name="white"/>
    </visual>
    <collision>
      <origin rpy="0 0 0" xyz="0 0 0"/>
      <geometry>
        <mesh filename="file:///home/match-mover/Documents/ros2_ws/install/pm_robot_description/share/pm_robot_description/meshes/Gonio_Right/Gonio_Right_Stage_1_Upper.STL"/>
      </geometry>
    </collision>
  </link>
  <!---Gravity off-->
  <gazebo reference="Gonio_Right_Stage_1_Top">
    <turnGravityOff>true</turnGravityOff>
  </gazebo>
  <joint name="Gonio_Right_Stage_1_Joint" type="revolute">
    <origin rpy="0 0 0" xyz="0.0324999999999993 0.0326774999999999 0.11"/>
    <parent link="Gonio_Right_Stage_1_Bottom"/>
    <child link="Gonio_Right_Stage_1_Top"/>
    <axis xyz="0 -1 0"/>
    <limit effort="100" lower="-0.087266" upper="0.087266" velocity="0.1"/>
  </joint>
  <!--%%%%%%%%%%%%% Gonio_Right Stage 2 Bottom Definitions-->
  <link name="Gonio_Right_Stage_2_Bottom">
    <inertial>
      <origin rpy="0 0 0" xyz="8.11599898398185E-10 -7.70700947505532E-10 -0.0578599597513433"/>
      <mass value="0.0546397543064688"/>
      <inertia ixx="1.83573872586574E-05" ixy="1.02198811435971E-11" ixz="3.03498623147601E-13" iyy="2.38958828661973E-05" iyz="8.61195754462734E-13" izz="3.93608749922961E-05"/>
    </inertial>
    <visual>
      <origin rpy="0 0 0" xyz="0 0 0"/>
      <geometry>
        <mesh filename="file:///home/match-mover/Documents/ros2_ws/install/pm_robot_description/share/pm_robot_description/meshes/Gonio_Right/Gonio_Right_Stage_2_Upper.STL"/>
      </geometry>
      <material name="grey"/>
    </visual>
    <collision>
      <origin rpy="0 0 0" xyz="0 0 0"/>
      <geometry>
        <mesh filename="file:///home/match-mover/Documents/ros2_ws/install/pm_robot_description/share/pm_robot_description/meshes/Gonio_Right/Gonio_Right_Stage_2_Upper.STL"/>
      </geometry>
    </collision>
  </link>
  <!---Gravity off-->
  <gazebo reference="Gonio_Right_Stage_2_Bottom">
    <turnGravityOff>true</turnGravityOff>
  </gazebo>
  <joint name="Gonio_Right_Stage_2_Joint" type="revolute">
    <origin rpy="0 0 0" xyz="0 0 0"/>
    <parent link="Gonio_Right_Stage_1_Top"/>
    <child link="Gonio_Right_Stage_2_Bottom"/>
    <axis xyz="-1 0 0"/>
    <limit effort="100" lower="-0.17453" upper="0.17453" velocity="0.1"/>
  </joint>
  <!--%%%%%%%%%%%%% Gonio Right Chuck Definitions-->
  <link name="Gonio_Right_Chuck_Origin">
  </link>
  <joint name="Gonio_Right_Chuck_Origin_Joint" type="fixed">
    <origin rpy="0 0 0" xyz="0 0 -0.0499999999999999"/>
    <parent link="Gonio_Right_Stage_2_Bottom"/>
    <child link="Gonio_Right_Chuck_Origin"/>
    <axis xyz="0 0 0"/>
  </joint>
  <link name="Gonio_Right_Chuck">
    <inertial>
      <origin rpy="0 0 0" xyz="-9.19297095559313E-19 -2.27077957540206E-18 0.0172248900305356"/>
      <mass value="0.129863306528145"/>
      <inertia ixx="4.82948612003887e-05" ixy="-3.25500417801018e-21" ixz="1.64704228720239e-21" iyy="4.99204835318359e-05" iyz="-1.66535047771477e-23" izz="7.72305136475402e-05"/>
    </inertial>
    <visual>
      <origin rpy="0 0 0" xyz="0 0 0"/>
      <geometry>
        <mesh filename="file:///home/match-mover/Documents/ros2_ws/install/pm_robot_description/share/pm_robot_description/meshes/Gonio_Right/Gonio_Right_Chucks/Chuck_Double_Lens_Holder_12_7.STL"/>
      </geometry>
      <material name="white">
    </material>
    </visual>
    <collision>
      <origin rpy="0 0 0" xyz="0 0 0"/>
      <geometry>
        <mesh filename="file:///home/match-mover/Documents/ros2_ws/install/pm_robot_description/share/pm_robot_description/meshes/Gonio_Right/Gonio_Right_Chucks/Chuck_Double_Lens_Holder_12_7.STL"/>
      </geometry>
    </collision>
  </link>
  <joint name="Gonio_Right_Chuck_Joint" type="fixed">
    <origin rpy="0 0 0" xyz="0 0 0"/>
    <parent link="Gonio_Right_Chuck_Origin"/>
    <child link="Gonio_Right_Chuck"/>
    <axis xyz="0 0 0"/>
  </joint>
  <!--%%%%%%%%%%%%% Gonio Right Part 1 Origin -->
  <link name="Gonio_Right_Part_1_Origin">
  </link>
  <joint name="Gonio_Right_Part_1_Origin_Joint" type="fixed">
    <origin rpy="0 0 0" xyz="0.009782273 0.0 0.056053231"/>
    <parent link="Gonio_Right_Chuck_Origin"/>
    <child link="Gonio_Right_Part_1_Origin"/>
    <axis xyz="0 0 0"/>
  </joint>
  <!--%%%%%%%%%%%%% Gonio Right Part 2 Origin -->
  <link name="Gonio_Right_Part_2_Origin">
  </link>
  <joint name="Gonio_Right_Part_2_Origin_Joint" type="fixed">
    <origin rpy="0 0 0" xyz="-0.009782273 0.0 0.056053231"/>
    <parent link="Gonio_Right_Chuck_Origin"/>
    <child link="Gonio_Right_Part_2_Origin"/>
    <axis xyz="0 0 0"/>
  </joint>
  <!-- Gonio Right old version-->
  <!-- <xacro:if value="$(arg with_Gonio_Right)">
    <xacro:pm_robot_gonio_right launch_mode="$(arg launch_mode)"/>
  </xacro:if> -->
  <!--%%%%%%%%%%%%% Gonio Station Left Definitions-->
  <link name="Gonio_Left_Base">
    <inertial>
      <origin rpy="0 0 0" xyz="0.177919402818021 0.0965286177417367 0.101012071345888"/>
      <mass value="4.83318674398637"/>
      <inertia ixx="0.0115127403940929" ixy="-3.33565784736103E-05" ixz="-1.45496624993124E-06" iyy="0.0188686138682557" iyz="-2.7618864699939E-05" izz="0.026985073699425"/>
    </inertial>
    <visual>
      <origin rpy="0 0 0" xyz="0 0 0"/>
      <geometry>
        <mesh filename="file:///home/match-mover/Documents/ros2_ws/install/pm_robot_description/share/pm_robot_description/meshes/Gonio_Left/Gonio_Left_Base.STL"/>
      </geometry>
      <material name="white"/>
    </visual>
    <collision>
      <origin rpy="0 0 0" xyz="0 0 0"/>
      <geometry>
        <mesh filename="file:///home/match-mover/Documents/ros2_ws/install/pm_robot_description/share/pm_robot_description/meshes/Gonio_Left/Gonio_Left_Base.STL"/>
      </geometry>
    </collision>
  </link>
  <joint name="Gonio_Left_Base_Joint" type="fixed">
    <origin rpy="0 0 0" xyz="0.14249999999998 0.295499999999939 0"/>
    <parent link="pm_robot_base_link"/>
    <child link="Gonio_Left_Base"/>
    <axis xyz="0 0 0"/>
  </joint>
  <!--%%%%%%%%%%%%% Gonio Left Stage 1 Top Definitions-->
  <link name="Gonio_Left_Stage_1_Top">
    <inertial>
      <origin rpy="0 0 0" xyz="0.059782487896749 0.00877925652714845 -0.0446785627316222"/>
      <mass value="0.578798857286943"/>
      <inertia ixx="0.000400478324367351" ixy="-0.000129239522587819" ixz="7.82346515336273E-07" iyy="0.00157904583991977" iyz="-5.25968237719779E-06" izz="0.00188005175520343"/>
    </inertial>
    <visual>
      <origin rpy="0 0 0" xyz="0 0 0"/>
      <geometry>
        <mesh filename="file:///home/match-mover/Documents/ros2_ws/install/pm_robot_description/share/pm_robot_description/meshes/Gonio_Left/Gonio_Left_Stage_1.STL"/>
      </geometry>
      <material name="grey"/>
    </visual>
    <collision>
      <origin rpy="0 0 0" xyz="0 0 0"/>
      <geometry>
        <mesh filename="file:///home/match-mover/Documents/ros2_ws/install/pm_robot_description/share/pm_robot_description/meshes/Gonio_Left/Gonio_Left_Stage_1.STL"/>
      </geometry>
    </collision>
  </link>
  <!---Gravity off-->
  <gazebo reference="Gonio_Left_Stage_1_Top">
    <turnGravityOff>true</turnGravityOff>
  </gazebo>
  <joint name="Gonio_Left_Stage_1_Joint" type="revolute">
    <origin rpy="0 0 0" xyz="0.188500000000042 0.110000000000054 0.212499999999997"/>
    <parent link="Gonio_Left_Base"/>
    <child link="Gonio_Left_Stage_1_Top"/>
    <axis xyz="1 0 0"/>
    <limit effort="100" lower="-0.17453" upper="0.17453" velocity="0.1"/>
  </joint>
  <!--%%%%%%%%%%%%% Gonio Left Stage 2 Bottom Definitions-->
  <link name="Gonio_Left_Stage_2_Bottom">
    <inertial>
      <origin rpy="0 0 0" xyz="4.69633887334453E-10 4.9960036108132E-16 -0.0212004572137997"/>
      <mass value="0.02706267019929"/>
      <inertia ixx="6.08758948397044E-06" ixy="4.1172957090613E-14" ixz="-8.65658801813879E-13" iyy="4.36785274885666E-06" iyz="-3.36683105860672E-21" izz="9.6064002937604E-06"/>
    </inertial>
    <visual>
      <origin rpy="0 0 0" xyz="0 0 0"/>
      <geometry>
        <mesh filename="file:///home/match-mover/Documents/ros2_ws/install/pm_robot_description/share/pm_robot_description/meshes/Gonio_Left/Gonio_Left_Stage_2.STL"/>
      </geometry>
      <material name="white"/>
    </visual>
    <collision>
      <origin rpy="0 0 0" xyz="0 0 0"/>
      <geometry>
        <mesh filename="file:///home/match-mover/Documents/ros2_ws/install/pm_robot_description/share/pm_robot_description/meshes/Gonio_Left/Gonio_Left_Stage_2.STL"/>
      </geometry>
    </collision>
  </link>
  <!---Gravity off-->
  <gazebo reference="Gonio_Left_Stage_2_Joint">
    <turnGravityOff>true</turnGravityOff>
  </gazebo>
  <joint name="Gonio_Left_Stage_2_Joint" type="revolute">
    <origin rpy="0 0 0" xyz="0 0 0"/>
    <parent link="Gonio_Left_Stage_1_Top"/>
    <child link="Gonio_Left_Stage_2_Bottom"/>
    <axis xyz="0 -1 0"/>
    <limit effort="100" lower="-0.17453" upper="0.17453" velocity="0.1"/>
  </joint>
  <!--%%%%%%%%%%%%% Gonio Left Chuck Definitions-->
  <link name="Gonio_Left_Chuck_Origin">
    </link>
  <joint name="Gonio_Left_Chuck_Origin_Joint" type="fixed">
    <origin rpy="0 0 0" xyz="0 0 -0.015"/>
    <parent link="Gonio_Left_Stage_2_Bottom"/>
    <child link="Gonio_Left_Chuck_Origin"/>
    <axis xyz="0 0 0"/>
  </joint>
  <link name="Gonio_Left_Chuck">
    <inertial>
      <origin rpy="0 0 0" xyz="2.67452024915572E-05 0.00473435482735033 0.0506333248330911"/>
      <mass value="0.11530970264759"/>
      <inertia ixx="2.48390077396091e-05" ixy="-8.88685892499368e-09" ixz="-3.6912429939074e-08" iyy="3.71154973701588e-05" iyz="-3.86161448630438e-07" izz="3.3978117134478e-05"/>
    </inertial>
    <visual>
      <origin rpy="0 0 0" xyz="0 0 0"/>
      <geometry>
        <mesh filename="file:///home/match-mover/Documents/ros2_ws/install/pm_robot_description/share/pm_robot_description/meshes/Gonio_Left/Gonio_Left_Chucks/Chuck_ipeg_Demonstrator.STL"/>
      </geometry>
      <material name="white">
        </material>
    </visual>
    <collision>
      <origin rpy="0 0 0" xyz="0 0 0"/>
      <geometry>
        <mesh filename="file:///home/match-mover/Documents/ros2_ws/install/pm_robot_description/share/pm_robot_description/meshes/Gonio_Left/Gonio_Left_Chucks/Chuck_ipeg_Demonstrator.STL"/>
      </geometry>
    </collision>
  </link>
  <joint name="Gonio_Left_Chuck_Joint" type="fixed">
    <origin rpy="0 0 0" xyz="0 0 0"/>
    <parent link="Gonio_Left_Chuck_Origin"/>
    <child link="Gonio_Left_Chuck"/>
    <axis xyz="0 0 0"/>
  </joint>
  <!--%%%%%%%%%%%%% Gonio Left Part Origin -->
  <link name="Gonio_Left_Part_Origin">
    </link>
  <joint name="Gonio_Left_Part_Origin_Joint" type="fixed">
    <origin rpy="0 0 0" xyz="0.01 0.015 0.10105"/>
    <parent link="Gonio_Left_Chuck_Origin"/>
    <child link="Gonio_Left_Part_Origin"/>
    <axis xyz="0 0 0"/>
  </joint>
  <!---Gravity off-->
  <gazebo reference="Gonio_Left_Chuck">
    <turnGravityOff>true</turnGravityOff>
  </gazebo>
  <!--%%%%%%%%%%%%% UV Slider X Front Definitions-->
  <link name="UV_Slider_X_Front">
    <inertial>
      <origin rpy="0 0 0" xyz="0.0678075668801579 -0.00614110312679139 0.0281452705871906"/>
      <mass value="0.123081615016624"/>
      <inertia ixx="5.17246869963476E-05" ixy="5.73233720860217E-08" ixz="1.10286553709345E-07" iyy="6.01963900555089E-05" iyz="-1.95135766107832E-09" izz="0.0001085863059652"/>
    </inertial>
    <visual>
      <origin rpy="0 0 0" xyz="0 0 0"/>
      <geometry>
        <mesh filename="file:///home/match-mover/Documents/ros2_ws/install/pm_robot_description/share/pm_robot_description/meshes/Gonio_Left/UV_Cart_X_Front.STL"/>
      </geometry>
      <material name="white"/>
    </visual>
    <collision>
      <origin rpy="0 0 0" xyz="0 0 0"/>
      <geometry>
        <mesh filename="file:///home/match-mover/Documents/ros2_ws/install/pm_robot_description/share/pm_robot_description/meshes/Gonio_Left/UV_Cart_X_Front.STL"/>
      </geometry>
    </collision>
  </link>
  <joint name="UV_Slider_X_Front_Joint" type="prismatic">
    <origin rpy="0 0 0" xyz="0.0785000000000391 0.0200000000000492 0.234999999999997"/>
    <parent link="Gonio_Left_Base"/>
    <child link="UV_Slider_X_Front"/>
    <axis xyz="1 0 0"/>
    <limit effort="100" lower="0" upper="0.095" velocity="0.05"/>
  </joint>
  <!--%%%%%%%%%%%%% UV LED Front Definitions-->
  <link name="UV_LED_Front">
    <inertial>
      <origin rpy="0 0 0" xyz="0.00149625706477036 0.00485466541438256 0.010590788590885"/>
      <mass value="0.119915229322348"/>
      <inertia ixx="8.58688559917156E-05" ixy="-9.33412701053303E-06" ixz="2.12947225159946E-07" iyy="1.98652848189388E-05" iyz="9.66953808700587E-07" izz="0.00010123498655613"/>
    </inertial>
    <visual>
      <origin rpy="0 0 0" xyz="0 0 0"/>
      <geometry>
        <mesh filename="file:///home/match-mover/Documents/ros2_ws/install/pm_robot_description/share/pm_robot_description/meshes/Gonio_Left/UV_Cart_Front.STL"/>
      </geometry>
      <material name="grey"/>
    </visual>
    <collision>
      <origin rpy="0 0 0" xyz="0 0 0"/>
      <geometry>
        <mesh filename="file:///home/match-mover/Documents/ros2_ws/install/pm_robot_description/share/pm_robot_description/meshes/Gonio_Left/UV_Cart_Front.STL"/>
      </geometry>
    </collision>
  </link>
  <joint name="UV_LED_Front_Joint" type="prismatic">
    <origin rpy="0 0 0" xyz="0.0649999999999999 -0.0540000000000002 0.0496999999988213"/>
    <parent link="UV_Slider_X_Front"/>
    <child link="UV_LED_Front"/>
    <axis xyz="0 1 0"/>
    <limit effort="100" lower="-0.0157" upper="0.0" velocity="0.5"/>
  </joint>
  <!--%%%%%%%%%%%%% UV Slider X Back Definitions-->
  <link name="UV_Slider_X_Back">
    <inertial>
      <origin rpy="0 0 0" xyz="0.0621924331202753 0.00614110312652594 0.0281452705830895"/>
      <mass value="0.123081615017413"/>
      <inertia ixx="5.17246869964295E-05" ixy="5.73233722279355E-08" ixz="-1.10286553628501E-07" iyy="6.01963900556179E-05" iyz="1.95135762598339E-09" izz="0.000108586305965351"/>
    </inertial>
    <visual>
      <origin rpy="0 0 0" xyz="0 0 0"/>
      <geometry>
        <mesh filename="file:///home/match-mover/Documents/ros2_ws/install/pm_robot_description/share/pm_robot_description/meshes/Gonio_Left/UV_Cart_X_Back.STL"/>
      </geometry>
      <material name="white"/>
    </visual>
    <collision>
      <origin rpy="0 0 0" xyz="0 0 0"/>
      <geometry>
        <mesh filename="file:///home/match-mover/Documents/ros2_ws/install/pm_robot_description/share/pm_robot_description/meshes/Gonio_Left/UV_Cart_X_Back.STL"/>
      </geometry>
    </collision>
  </link>
  <joint name="UV_Slider_X_Back_Joint" type="prismatic">
    <origin rpy="0 0 0" xyz="0.0785000000000389 0.200000000000049 0.234999999999998"/>
    <parent link="Gonio_Left_Base"/>
    <child link="UV_Slider_X_Back"/>
    <axis xyz="1 0 0"/>
    <limit effort="0.05" lower="0" upper="0.045" velocity="100"/>
  </joint>
  <!--%%%%%%%%%%%%% UV LED Back Definitions-->
  <link name="UV_LED_Back">
    <inertial>
      <origin rpy="0 0 0" xyz="-0.00149625706477086 -0.00485466541438306 0.0105907885908847"/>
      <mass value="0.119915229322348"/>
      <inertia ixx="8.58688559917144E-05" ixy="-9.33412701053305E-06" ixz="-2.12947225160345E-07" iyy="1.98652848189388E-05" iyz="-9.66953808700748E-07" izz="0.000101234986556129"/>
    </inertial>
    <visual>
      <origin rpy="0 0 0" xyz="0 0 0"/>
      <geometry>
        <mesh filename="file:///home/match-mover/Documents/ros2_ws/install/pm_robot_description/share/pm_robot_description/meshes/Gonio_Left/UV_Cart_Back.STL"/>
      </geometry>
      <material name="grey"/>
    </visual>
    <collision>
      <origin rpy="0 0 0" xyz="0 0 0"/>
      <geometry>
        <mesh filename="file:///home/match-mover/Documents/ros2_ws/install/pm_robot_description/share/pm_robot_description/meshes/Gonio_Left/UV_Cart_Back.STL"/>
      </geometry>
    </collision>
  </link>
  <joint name="UV_LED_Back_Joint" type="prismatic">
    <origin rpy="0 0 0" xyz="0.0649999999999949 0.0539999999999998 0.0496999999948266"/>
    <parent link="UV_Slider_X_Back"/>
    <child link="UV_LED_Back"/>
    <axis xyz="0 1 0"/>
    <limit effort="100" lower="-0.0157" upper="0.0" velocity="0.05"/>
  </joint>
  <!-- Gonio Left old version-->
  <!-- <xacro:if value="$(arg with_Gonio_Left)">
    <xacro:pm_robot_gonio_left launch_mode="$(arg launch_mode)"/>
  </xacro:if> -->
  <!-- END - Gonio Defines-->
  <!--%%%%%%%%%% Camera_Top_View -->
  <link name="Camera_Top_View_Link"/>
  <joint name="Camera_Top_View_Link_Joint" type="fixed">
    <parent link="Cam1_Toolhead_TCP"/>
    <child link="Camera_Top_View_Link"/>
    <origin rpy="0 1.570796 0 " xyz="0.02 0.021 -0.16"/>
  </joint>
  <link name="Camera_Top_View_Link_Optical"/>
  <joint name="Camera_Top_View_Link_Optical_Joint" type="fixed">
    <parent link="Camera_Top_View_Link"/>
    <child link="Camera_Top_View_Link_Optical"/>
    <origin rpy="-1.570796 0 -1.570796 " xyz="0 0 0"/>
  </joint>
  <gazebo reference="Camera_Top_View_Link">
    <sensor name="Cam1" type="camera">
      <pose>0 0 0 0 0 0 </pose>
      <!-- <visualize>true</visualize> -->
      <!-- <update_rate>14.6</update_rate> -->
      <camera name="head">
        <horizontal_fov>1.050453012</horizontal_fov>
        <image>
          <width>2592</width>
          <height>1942</height>
          <format>L8</format>
        </image>
        <clip>
          <near>0.1</near>
          <far>0.214</far>
        </clip>
        <lens>
          <type>orthographic</type>
          <scale_to_hfov>true</scale_to_hfov>
        </lens>
      </camera>
      <plugin filename="libgazebo_ros_camera.so" name="camera_controller_cam1">
        <topicName>pm_robot_description/cam1</topicName>
        <frameName>Camera_Top_View_Link_Optical</frameName>
      </plugin>
    </sensor>
  </gazebo>
  <!--%%%%%%%%%% Camera_Bottom_View -->
  <link name="Camera_Bottom_View_Link"/>
  <joint name="Camera_Bottom_View_Joint" type="fixed">
    <parent link="Camera_Station_TCP"/>
    <child link="Camera_Bottom_View_Link"/>
    <origin rpy="0 -1.570796 0 " xyz="0.0 0 -0.754"/>
  </joint>
  <link name="Camera_Bottom_View_Link_Optical"/>
  <joint name="Camera_Bottom_View_Link_Optical_Joint" type="fixed">
    <parent link="Camera_Bottom_View_Link"/>
    <child link="Camera_Bottom_View_Link_Optical"/>
    <origin rpy="-1.570796 0 -1.570796 " xyz="0 0 0"/>
  </joint>
  <gazebo reference="Camera_Bottom_View_Link">
    <sensor name="Cam2" type="camera">
      <pose>0 0 0 0 0 0 </pose>
      <visualize>true</visualize>
      <update_rate>14.6</update_rate>
      <camera name="bottom">
        <horizontal_fov>0.01</horizontal_fov>
        <image>
          <width>2592</width>
          <height>1942</height>
          <format>L8</format>
        </image>
        <clip>
          <near>0.9</near>
          <far>2.13</far>
        </clip>
        <!-- <lens>
          <type>orthographic</type>
        </lens> -->
      </camera>
      <plugin filename="libgazebo_ros_camera.so" name="camera_controller_cam2">
        <topicName>pm_robot_description/cam2</topicName>
        <frameName>Camera_Bottom_View_Link_Optical</frameName>
      </plugin>
    </sensor>
  </gazebo>
  <!-- Laser -->
  <link name="laser_top_link"/>
  <joint name="laser_top_joint" type="fixed">
    <parent link="Z_Axis"/>
    <child link="laser_top_link"/>
    <origin rpy="-1.570796 1.570796 0 " xyz="-0.08 0.122 -0.48"/>
  </joint>
  <gazebo reference="laser_top_link">
    <sensor name="laser_top" type="gpu_ray">
      <pose>0 0 0 0 0 0</pose>
      <visualize>true</visualize>
      <update_rate>40</update_rate>
      <ray>
        <scan>
          <horizontal>
            <samples>720</samples>
            <resolution>1</resolution>
            <min_angle>-0.1</min_angle>
            <max_angle>0.1</max_angle>
          </horizontal>
        </scan>
        <range>
          <min>0.0057</min>
          <max>0.0063</max>
          <resolution>0.0001</resolution>
        </range>
        <!-- <noise>
          <type>gaussian</type>
          Noise parameters based on published spec for Hokuyo laser
               achieving "+-30mm" accuracy at range < 10m.  A mean of 0.0m and
               stddev of 0.01m will put 99.7% of samples within 0.03m of the true
               reading.
          <mean>0.0</mean>
          <stddev>0.01</stddev>
        </noise> -->
      </ray>
      <plugin filename="libgazebo_ros_gpu_laser.so" name="gazebo_ros_head_hokuyo_controller">
        <topicName>laser/scan</topicName>
        <frameName>laser_top_link</frameName>
      </plugin>
    </sensor>
  </gazebo>
  <!-- Switch between Gazebo-Simulation and Real Robot -->
  <ros2_control name="GazeboSystem" type="system">
    <hardware>
      <plugin>gazebo_ros2_control/GazeboSystem</plugin>
    </hardware>
    <joint name="X_Axis_Joint">
      <command_interface name="position">
                </command_interface>
      <state_interface name="position"/>
      <state_interface name="velocity"/>
    </joint>
    <joint name="Y_Axis_Joint">
      <command_interface name="position">
                </command_interface>
      <state_interface name="position"/>
      <state_interface name="velocity"/>
    </joint>
    <joint name="Z_Axis_Joint">
      <command_interface name="position">
                </command_interface>
      <state_interface name="position"/>
      <state_interface name="velocity"/>
    </joint>
    <joint name="T_Axis_Joint">
      <command_interface name="position">
                </command_interface>
      <state_interface name="position"/>
      <state_interface name="velocity"/>
    </joint>
    <joint name="1K_Dispenser_Flap_Joint">
      <command_interface name="position">
                </command_interface>
      <state_interface name="position"/>
    </joint>
    <joint name="1K_Dispenser_Joint">
      <command_interface name="position">
                </command_interface>
      <state_interface name="position"/>
    </joint>
    <joint name="2K_Dispenser_Joint">
      <command_interface name="position">
                </command_interface>
      <state_interface name="position"/>
    </joint>
    <joint name="Gonio_Right_Stage_1_Joint">
      <command_interface name="position">
                </command_interface>
      <state_interface name="position"/>
    </joint>
    <joint name="Gonio_Right_Stage_2_Joint">
      <command_interface name="position">
                </command_interface>
      <state_interface name="position"/>
    </joint>
    <joint name="Camera_Calibration_Platelet_Joint">
      <command_interface name="position">
                </command_interface>
      <state_interface name="position"/>
    </joint>
    <joint name="Gonio_Left_Stage_1_Joint">
      <command_interface name="position">
                </command_interface>
      <state_interface name="position"/>
    </joint>
    <joint name="Gonio_Left_Stage_2_Joint">
      <command_interface name="position">
                </command_interface>
      <state_interface name="position"/>
    </joint>
    <joint name="UV_Slider_X_Front_Joint">
      <command_interface name="position">
                </command_interface>
      <state_interface name="position"/>
    </joint>
    <joint name="UV_LED_Front_Joint">
      <command_interface name="position">
                </command_interface>
      <state_interface name="position"/>
    </joint>
    <joint name="UV_Slider_X_Back_Joint">
      <command_interface name="position">
                </command_interface>
      <state_interface name="position"/>
    </joint>
    <joint name="UV_LED_Back_Joint">
      <command_interface name="position">
                </command_interface>
      <state_interface name="position"/>
    </joint>
    <joint name="Calibration_Qube_Joint">
      <command_interface name="position">
                </command_interface>
      <state_interface name="position"/>
    </joint>
  </ros2_control>
  <gazebo>
    <plugin filename="libgazebo_ros2_control.so" name="gazebo_ros2_control">
      <parameters>/home/match-mover/Documents/ros2_ws/install/pm_robot_description/share/pm_robot_description/config/pm_robot_control_sim_HW.yaml</parameters>
      <parameters>/home/match-mover/Documents/ros2_ws/install/pm_robot_description/share/pm_robot_description/config/pm_robot_control_gonio_right_sim_HW.yaml</parameters>
      <parameters>/home/match-mover/Documents/ros2_ws/install/pm_robot_description/share/pm_robot_description/config/pm_robot_control_gonio_left_sim_HW.yaml</parameters>
      <!-- <xacro:if value="$(arg with_Tool_MPG_10)">
                    <parameters>$(find pm_robot_description)/config/pm_robot_control_gripper_sim_HW.yaml</parameters>
                </xacro:if> -->
      <!--robot_param>robot_description</robot_param-->
      <!--The location of the robot_description (URDF) on the parameter server, defaults to robot_description-->
      <!--robot_param_node>robot_state_publisher</robot_param_node-->
      <!-- Name of the node where the robot_param is located, defauls to robot_state_publisher-->
      <!--robotNamespace>${arm_id}</robotNamespace-->
    </plugin>
  </gazebo>
</robot>
