<?xml version="1.0" encoding="utf-8"?>
<!-- This URDF was automatically created by SolidWorks to URDF Exporter! Originally created by Stephen Brawner (brawner@gmail.com) 
     Commit Version: 1.6.0-1-g15f4949  Build Version: 1.6.7594.29634
     For more information, please see http://wiki.ros.org/sw_urdf_exporter -->
<robot name="pm_robot">

  <link name="world">
  </link>

  <joint name="world_joint" type="fixed">
    <parent link="world"/>
    <child link="base_link"/>
    <origin xyz="0 0 0" rpy="0 0 0" />
  </joint>

  <!-- <gazebo reference="base_link">
    <material>Gazebo/Blue</material>
  </gazebo> -->

  <!-- <gazebo reference="Component">
    <material>Gazebo/White</material>
</gazebo> -->

 <!--%%%%%%%%%%%%% Base Link Definitions %%%%%%%%%%%%%-->
  <link name="base_link">
    <inertial>
      <origin xyz="0.625821801363778 0.570133136306886 0.131114542394431" rpy="0 0 0" />
      <mass value="185.737269065976" />
      <inertia ixx="17.6891686329467" ixy="-0.0005539539064769" ixz="2.11795920498451E-05" iyy="19.5856182457273" iyz="0.00180194516552895" izz="36.6182068946149" />
    </inertial>
    <visual>
      <origin xyz="0 0 0" rpy="0 0 0" />
      <geometry>
        <mesh filename="file://$(find pm_robot_description)/meshes/base_link.STL" />
      </geometry>
      <material name="grey"/>
    </visual>
    <collision>
      <origin xyz="0 0 0" rpy="0 0 0" />
      <geometry>
        <mesh filename="file://$(find pm_robot_description)/meshes/base_link.STL" />
      </geometry>

    </collision>
  </link>
 <!--%%%%%%%%%%%%% X Axis Definitions %%%%%%%%%%%%%-->
  <link name="X_Axis">
    <inertial>
      <origin xyz="0.16919895741484 -0.139025494621401 0.0270399805740182" rpy="0 0 0" />
      <mass value="3.40836170630821" />
      <inertia ixx="0.0248404376541355" ixy="-0.000748520694827292" ixz="6.13257340524014E-06" iyy="0.0088330828502041" iyz="-2.4288100595453E-05" izz="0.0333342630400324" />
    </inertial>
    <visual>
      <origin xyz="0 0 0" rpy="0 0 0" />
      <geometry>
        <mesh filename="file://$(find pm_robot_description)/meshes/X_Axis.STL" />
      </geometry>
      <material name="orange"/>
    </visual>
    <collision>
      <origin xyz="0 0 0" rpy="0 0 0" />
      <geometry>
        <mesh filename="file://$(find pm_robot_description)/meshes/X_Axis.STL" />
      </geometry>
    </collision>
  </link>

  <joint name="X_Axis_Joint" type="prismatic">
    <origin xyz="0.19 0.5545 0.56" rpy="0 0 0" />
    <parent link="base_link" />
    <child link="X_Axis" />
    <axis xyz="-1 0 0" />
    <limit lower="-0.745" upper="0.055" effort="0.1" velocity="100" />
  </joint>
 <!--%%%%%%%%%%%%% Y Axis Definitions %%%%%%%%%%%%%-->
  <link name="Y_Axis">
    <inertial>
      <origin xyz="0.0644731605204091 0.335953761487189 0.0959734258135516" rpy="0 0 0" />
      <mass value="5.14878388645621" />
      <inertia ixx="0.0689971056038874" ixy="-5.48415730832886E-06" ixz="0.000161589759460467" iyy="0.0347519976611458" iyz="-0.00648361648669565" izz="0.0562521130143104" />
    </inertial>
    <visual>
      <origin xyz="0 0 0" rpy="0 0 0" />
      <geometry>
        <mesh filename="file://$(find pm_robot_description)/meshes/Y_Axis.STL" />
      </geometry>
      <material name="brown"/>
    </visual>
    <collision>
      <origin xyz="0 0 0" rpy="0 0 0" />
      <geometry>
        <mesh filename="file://$(find pm_robot_description)/meshes/Y_Axis.STL" />
      </geometry>
    </collision>
  </link>

  <joint name="Y_Axis_Joint" type="prismatic">
    <origin xyz="0.1115 -0.39197 0.0625" rpy="0 0 0" />
    <parent link="X_Axis" />
    <child link="Y_Axis" />
    <axis xyz="0 -1 0" />
    <limit lower="-0.134000" upper="-0.019700" effort="100" velocity="100" />
  </joint>
 <!--%%%%%%%%%%%%% Z Axis Definitions %%%%%%%%%%%%%-->
  <link name="Z_Axis">
    <inertial>
      <origin xyz="0.0549049098594834 0.0430017751887579 -0.271974089543362" rpy="0 0 0" />
      <mass value="2.90435657697672" />
      <inertia ixx="0.0172042502712429" ixy="-1.43162614116986E-05" ixz="0.000234498173213759" iyy="0.0221198084238349" iyz="9.06231760054573E-05" izz="0.00612331848936254" />
    </inertial>
    <visual>
      <origin xyz="0 0 0" rpy="0 0 0" />
      <geometry>
        <mesh filename="file://$(find pm_robot_description)/meshes/Z_Axis.STL" />
      </geometry>
      <material name="blue"/>
    </visual>
    <collision>
      <origin xyz="0 0 0" rpy="0 0 0" />
      <geometry>
        <mesh filename="file://$(find pm_robot_description)/meshes/Z_Axis.STL" />
      </geometry>
    </collision>
  </link>
  <!---Gravity off-->
  <gazebo reference="Z_Axis">
    <turnGravityOff>true</turnGravityOff>
  </gazebo>

  <joint name="Z_Axis_Joint" type="prismatic">
    <origin xyz="-0.000999999553101816 0.496199999543101 0.2825180193463" rpy="0 0 0" />
    <parent link="Y_Axis" />
    <child link="Z_Axis" />
    <axis xyz="0 0 -1" />
    <limit lower="-0.05262" upper="0.055" effort="100" velocity="0.05" />
  </joint>

   <!--%%%%%%%%%%%%% T Axis Definitions %%%%%%%%%%%%%-->
  <link name="Gripper_Rot_Plate">
    <inertial>
      <origin xyz="2.0103346298761E-07 1.7706926014327E-07 -0.0164220765723002" rpy="0 0 0" />
      <mass value="0.11029725831735" />
      <inertia ixx="8.79764941917058E-05" ixy="-1.83626185977477E-10" ixz="-1.48320232213546E-10" iyy="8.79759415900838E-05" iyz="-1.27560286892208E-10" izz="0.000165659871028387" />
    </inertial>
    <visual>
      <origin xyz="0 0 0" rpy="0 0 0" />
      <geometry>
        <mesh filename="file://$(find pm_robot_description)/meshes/Gripper_Rot_Plate.STL" />
      </geometry>
      <material name="black"/>
    </visual>
    <collision>
      <origin xyz="0 0 0" rpy="0 0 0" />
      <geometry>
        <mesh filename="file://$(find pm_robot_description)/meshes/Gripper_Rot_Plate.STL" />
      </geometry>
    </collision>
  </link>

  <!---Gravity off-->
  <gazebo reference="Gripper_Rot_Plate">
    <turnGravityOff>true</turnGravityOff>
  </gazebo>

  <joint name="Gripper_Rot_Plate_Joint" type="revolute">
    <origin xyz="0.00750000000002338 0.0900000062570287 -0.389499999999991" rpy="0 0 0" />
    <parent link="Z_Axis" />
    <child link="Gripper_Rot_Plate" />
    <axis xyz="0 0 1" />
    <limit lower="0" upper="12" effort="100" velocity="2" />
  </joint>
  
  <!--
  Gripper Definitions
  <link name="Gripper">
    <inertial>            </command_interface>
" ixy="-1.96701975168782E-08" ixz="3.35250198834726E-09" iyy="2.52844539238953E-05" iyz="4.55516572819596E-10" izz="4.09732369514151E-05" />
    </inertial>
    <visual>
      <origin xyz="0 0 0" rpy="0 0 0" />
      <geometry>
        <mesh filename="file://$(find pm_robot_description)/meshes/Gripper.STL" />
      </geometry>
    </visual>
    <collision>
      <origin xyz="0 0 0" rpy="0 0 0" />
      <geometry>
        <mesh filename="file://$(find pm_robot_description)/meshes/Gripper.STL" />
      </geometry>
    </collision>
  </link>

  <gazebo reference="Gripper">
    <turnGravityOff>true</turnGravityOff>
  </gazebo>

  <joint name="Gripper_Joint" type="fixed">
    <origin xyz="0 0 -0.096" rpy="0 0 0" />
    <parent link="Gripper_Rot_Plate" />
    <child link="Gripper" />
    <axis xyz="0 0 0" />
  </joint>
-->

   <!--%%%%%%%%%%%%% 1K Dispenser Flap Definitions %%%%%%%%%%%%%-->
  <link name="1K_Dispenser_Flap">
    <inertial>
      <origin xyz="0.0700781843320345 0.0170691077164346 -0.0129807443134493" rpy="0 0 0" />
      <mass value="0.0179277924431146" />
      <inertia ixx="4.17419773394052E-06" ixy="1.29835566651964E-07" ixz="-6.29537316660378E-08" iyy="5.0332526265048E-06" iyz="-9.02306176061445E-09" izz="4.11888432036329E-06" />
    </inertial>
    <visual>
      <origin xyz="0 0 0" rpy="0 0 0" />
      <geometry>
        <mesh filename="file://$(find pm_robot_description)/meshes/1K_Dispenser_Flap.STL" />
      </geometry>
      <material name="white"/>
    </visual>
    <collision>
      <origin xyz="0 0 0" rpy="0 0 0" />
      <geometry>
        <mesh filename="file://$(find pm_robot_description)/meshes/1K_Dispenser_Flap.STL" />
      </geometry>
    </collision>
  </link>
  <!---Gravity off-->
  <gazebo reference="1K_Dispenser_Flap">
    <turnGravityOff>true</turnGravityOff>
  </gazebo>

  <joint name="1K_Dispenser_Flap_Joint" type="prismatic">
    <origin xyz="0.075 0.0545 -0.4125" rpy="0 0 0" />
    <parent link="Z_Axis" />
    <child link="1K_Dispenser_Flap" />
    <axis xyz="-1 0 0" />
    <limit lower="0" upper="0.02" effort="100" velocity="0.05" />
  </joint>

   <!--%%%%%%%%%%%%% 1K Dispenser Definitions %%%%%%%%%%%%%-->
  <link name="1K_Dispenser">
    <inertial>
      <origin xyz="0.00152170573859456 -0.0155689227694598 0.0732771947044504" rpy="0 0 0" />
      <mass value="0.0725671789847037" />
      <inertia ixx="3.42933852018174E-05" ixy="-1.9196779157754E-07" ixz="5.6266438742732E-08" iyy="3.40475356608841E-05" iyz="-5.66364139854928E-07" izz="1.14639175060998E-05" />
    </inertial>
    <visual>
      <origin xyz="0 0 0" rpy="0 0 0" />
      <geometry>
        <mesh filename="file://$(find pm_robot_description)/meshes/1K_Dispenser.STL" />
      </geometry>
      <material name="red"/>
    </visual>
    <collision>
      <origin xyz="0 0 0" rpy="0 0 0" />
      <geometry>
        <mesh filename="file://$(find pm_robot_description)/meshes/1K_Dispenser.STL" />
      </geometry>
    </collision>
  </link>
  <!---Gravity off-->
  <gazebo reference="1K_Dispenser">
    <turnGravityOff>true</turnGravityOff>
  </gazebo>

  <joint name="1K_Dispenser_Joint" type="prismatic">
    <origin xyz="0.1725 0.09 -0.4655" rpy="0 0 0" />
    <parent link="Z_Axis" />
    <child link="1K_Dispenser" />
    <axis xyz="0 0 -1" />
    <limit lower="0" upper="0.04" effort="100" velocity="0.05" />
  </joint>

   <!--%%%%%%%%%%%%% 2K Dispenser Definitions-->
  <link name="2K_Dispenser">
    <inertial>
      <origin xyz="-7.70076275026232E-05 -0.00407732001221047 0.227924914909323" rpy="0 0 0" />
      <mass value="0.313852053537918" />
      <inertia ixx="0.00144466288151759" ixy="-1.68460920250166E-06" ixz="4.60612004407554E-08" iyy="0.00144815492756172" iyz="6.36164062970036E-07" izz="7.84175515924672E-05" />
    </inertial>
    <visual>
      <origin xyz="0 0 0" rpy="0 0 0" />
      <geometry>
        <mesh filename="file://$(find pm_robot_description)/meshes/2K_Dispenser.STL" />
      </geometry>
      <material name="orange"/>
    </visual>
    <collision>
      <origin xyz="0 0 0" rpy="0 0 0" />
      <geometry>
        <mesh filename="file://$(find pm_robot_description)/meshes/2K_Dispenser.STL" />
      </geometry>
    </collision>
  </link>
  <!---Gravity off-->
  <gazebo reference="2K_Dispenser">
    <turnGravityOff>true</turnGravityOff>
  </gazebo>

  <joint name="2K_Dispenser_Joint" type="prismatic">
    <origin xyz="0.2365 0.0618 -0.4695" rpy="0 0 0" />
    <parent link="Z_Axis" />
    <child link="2K_Dispenser" />
    <axis xyz="0 0 1" />
    <limit lower="0" upper="0.02" effort="100" velocity="0.05" />
  </joint>

   <!--%%%%%%%%%%%%% Top Camera Definitions-->
  <link name="Camera_Top_View">
    <inertial>
      <origin xyz="-0.00836863839426638 -7.6879236264973E-05 0.0937623632384506" rpy="0 0 0" />
      <mass value="0.0744906107551854" />
      <inertia ixx="3.47731720414153E-05" ixy="6.43752140750263E-10" ixz="3.28409092724849E-07" iyy="3.75323274030922E-05" iyz="1.11954348594254E-07" izz="9.81037833809299E-06" />
    </inertial>
    <visual>
      <origin xyz="0 0 0" rpy="0 0 0" />
      <geometry>
        <mesh filename="file://$(find pm_robot_description)/meshes/Camera_Top_View.STL" />
      </geometry>
      <material name="white"/>
    </visual>
    <collision>
      <origin xyz="0 0 0" rpy="0 0 0" />
      <geometry>
        <mesh filename="file://$(find pm_robot_description)/meshes/Camera_Top_View.STL" />
      </geometry>
    </collision>
  </link>
  <!---Gravity off-->
  <gazebo reference="Camera_Top_View">
    <turnGravityOff>true</turnGravityOff>
  </gazebo>

  <joint name="Camera_Top_View_Joint" type="fixed">
    <origin xyz="0.0795000000000243 0.068500020970708 -0.233999999999991" rpy="0 0 0" />
    <parent link="Z_Axis" />
    <child link="Camera_Top_View" />
    <axis xyz="0 0 0" />
  </joint>

  <!--%%%%%%%%%%%%% Test Station Definitions-->
  <link name="Test_Station">
    <inertial>
      <origin xyz="0.0375 0.109867595364853 0.143148862667039" rpy="0 0 0" />
      <mass value="1.39099524679326" />
      <inertia ixx="0.00780193904512034" ixy="-2.61716248057058E-14" ixz="-3.61572424102462E-21" iyy="0.00547600691976027" iyz="-9.87499782880815E-10" izz="0.00281708795214925" />
    </inertial>
    <visual>
      <origin xyz="0 0 0" rpy="0 0 0" />
      <geometry>
        <mesh filename="file://$(find pm_robot_description)/meshes/Test_Station.STL" />
      </geometry>
      <material name="grey"/>
    </visual>
    <collision>
      <origin xyz="0 0 0" rpy="0 0 0" />
      <geometry>
        <mesh filename="file://$(find pm_robot_description)/meshes/Test_Station.STL" />
      </geometry>
    </collision>
  </link>

  <joint name="Test_Station_Joint" type="fixed">
    <origin xyz="1.0625 0.6845 0.1" rpy="0 0 0" />
    <parent link="base_link" />
    <child link="Test_Station" />
    <axis xyz="0 0 0" />
  </joint>
  
  <!-- <link name="Component">
    <inertial>
      <origin xyz="0.0347500000000016 0.0327000000000096 0.0533550000000003" rpy="0 0 0" />
      <mass value="0.00104831550000006" />
      <inertia ixx="3.55496103757146E-08" ixy="1.89981381540481E-23" ixz="2.41620205931236E-23" iyy="8.15217394357171E-08" iyz="8.32325538551038E-24" izz="1.16560453252507E-07" />
    </inertial>
    <visual>
      <origin xyz="0 0 0" rpy="0 0 0" />
      <geometry>
        <mesh filename="package://robot_image_recognition/meshes/Component.STL" />
      </geometry>
      <material name="">
        <color rgba="0.792156862745098 0.819607843137255 0.933333333333333 2" />
      </material>
    </visual>
    <collision>
      <origin xyz="0 0 0" rpy="0 0 0" />
      <geometry>
        <mesh filename="package://robot_image_recognition/meshes/Component.STL" />
      </geometry>
    </collision>
  </link>
  <joint name="Component_Joint" type="fixed">
    <origin xyz="0 0 0" rpy="0 0 0" />
    <parent link="Nest" />
    <child link="Component" />
    <axis xyz="0 0 0" />
  </joint> -->

  <!--%%%%%%%%%%%%% Camera Definitions-->
  <link name="Camera_System">
    <inertial>
      <origin xyz="0.0505028321627497 0.194735930802516 0.146786757354195" rpy="0 0 0" />
      <mass value="2.8858378823955" />
      <inertia ixx="0.0184869737843273" ixy="1.26297079346321E-05" ixz="3.42211569734802E-06" iyy="0.0045547035395917" iyz="-9.47292848293822E-05" izz="0.0194720270517019" />
    </inertial>
    <visual>
      <origin xyz="0 0 0" rpy="0 0 0" />
      <geometry>
        <mesh filename="file://$(find pm_robot_description)/meshes/Camera_System.STL" />
      </geometry>
      <material name="white"/>
    </visual>
    <collision>
      <origin xyz="0 0 0" rpy="0 0 0" />
      <geometry>
        <mesh filename="file://$(find pm_robot_description)/meshes/Camera_System.STL" />
      </geometry>
    </collision>
  </link>

  <joint name="Camera_System_Joint" type="fixed">
    <origin xyz="0.6025 0.5075 0.1" rpy="0 0 0" />
    <parent link="base_link" />
    <child link="Camera_System" />
    <axis xyz="0 0 0" />
  </joint>

  <!--%%%%%%%%%%%%% Camera Calibration Definitions-->
  <link name="Camera_Calibration">
    <inertial>
      <origin xyz="-2.23806848806962E-05 -0.0716494371536874 0.0040939089037404" rpy="0 0 0" />
      <mass value="0.0326858647412389" />
      <inertia ixx="2.04982158767326E-05" ixy="-1.61006130053567E-08" ixz="3.66083708051192E-11" iyy="2.64269352598525E-06" iyz="-4.64472618194221E-07" izz="2.23690961977999E-05" />
    </inertial>
    <visual>
      <origin xyz="0 0 0" rpy="0 0 0" />
      <geometry>
        <mesh filename="file://$(find pm_robot_description)/meshes/Camera_Calibration.STL" />
      </geometry>
      <material name="green"/>
    </visual>
    <collision>
      <origin xyz="0 0 0" rpy="0 0 0" />
      <geometry>
        <mesh filename="file://$(find pm_robot_description)/meshes/Camera_Calibration.STL" />
      </geometry>
    </collision>
  </link>

  <joint name="Camera_Calibartion_Joint" type="prismatic">
    <origin xyz="0.065 0.4615 0.293" rpy="0 0 0" />
    <parent link="Camera_System" />
    <child link="Camera_Calibration" />
    <axis xyz="0 1 0" />
    <limit lower="-0.04" upper="0.0" effort="100" velocity="0.05" />
  </joint>

</robot> 
